Workbook

Sheet 01-07-26
A1: SRI MK PAPER MILLS PVT. LTD.
A3: CHEMICAL CONSUMPTION / BALANCE & COSTING PER DAY & TODATE
A4: PRODUCTION ( MT ) | E4: 170 | F4: 170 | G4: 170.000(AVG) | H4: DATE : 01 - 07 - 2026
A5: PRODUCTION (MT) | C5: GOLDEN YELLOW | E5: 0 | F5: 0 | G5: 000.000(AVG)
A6: SR. | B6: CHEMICAL | C6: OPENING | D6: RECEIVED MATERIAL | F6: CONSUMED MATERIAL | H6: TODAY | I6: CHEMICAL | J6: TO DATE | K6: RATE | L6: TOTAL CONSUMED AMOUNT | N6: COSTING
A7: NO. | B7: NAME | C7: STOCK | D7: TO DAY | E7: TO DATE | F7: TO DAY | G7: TO DATE | H7: CONSUMPTION | I7: BALANCE | J7: CONSUMPTION | K7: RS.@ | L7: TODAY | M7: TO DATE | N7: TODAY | O7: TO DATE
C8: (Kgs.) | D8: (Kgs.) | E8: (Kgs.) | F8: (Kgs.) | G8: (Kgs.) | H8: (Kgs.)/MTP | I8: (Kgs.) | J8: (Kgs.)/MTP | K8: MT | L8: Rs. | M8: Rs. | N8: Rs./MTP | O8: Rs./MTP
A9: 1 | B9: STARCH | C9: 13400 | F9: 3900 | G9: 3900 | H9: =F9/E4 -> 22.941176 | I9: =(C9-F9)+D9 -> 9500 | J9: =G9/F4 -> 22.941176 | K9: 28500 | L9: =(F9/1000)*K9 -> 111150 | M9: =(G9/1000)*K9 -> 111150 | N9: =L9/E4 -> 653.82353 | O9: =M9/F4 -> 653.82353
A10: 2 | B10: PAC ( SOLID) | C10: 9000 | F10: 222 | G10: 222 | H10: =F10/E4 -> 1.3058824 | I10: =(C10-F10)+D10 -> 8778 | J10: =G10/F4 -> 1.3058824 | K10: 35500 | L10: =(F10/1000)*K10 -> 7881 | M10: =(G10/1000)*K10 -> 7881 | N10: =L10/E4 -> 46.358824 | O10: =M10/F4 -> 46.358824
A11: 3 | B11: SURFACE SIZE (700C) | C11: 6820 | F11: 77 | G11: 77 | H11: =F11/E4 -> 0.45294118 | I11: =(C11-F11)+D11 -> 6743 | J11: =G11/F4 -> 0.45294118 | K11: 98000 | L11: =(F11/1000)*K11 -> 7546 | M11: =(G11/1000)*K11 -> 7546 | N11: =L11/E4 -> 44.388235 | O11: =M11/F4 -> 44.388235
A12: 4 | B12: ENZYME (L) | C12: 21 | F12: 0.08 | G12: 0.08 | H12: =F12/E4 -> 0.00047058824 | I12: =(C12-F12)+D12 -> 20.92 | J12: =G12/F4 -> 0.00047058824 | K12: 750000 | L12: =(F12/1000)*K12 -> 60 | M12: =(G12/1000)*K12 -> 60 | N12: =L12/E4 -> 0.35294118 | O12: =M12/F4 -> 0.35294118
A13: 5 | B13: RETENTION AID (2024) | C13: 500 | F13: 21 | G13: 21 | H13: =F13/E4 -> 0.12352941 | I13: =(C13-F13)+D13 -> 479 | J13: =G13/F4 -> 0.12352941 | K13: 350000 | L13: =(F13/1000)*K13 -> 7350 | M13: =(G13/1000)*K13 -> 7350 | N13: =L13/E4 -> 43.235294 | O13: =M13/F4 -> 43.235294
A14: 6 | B14: DEFOAMER (SE 100) | C14: 2400 | F14: 80 | G14: 80 | H14: =F14/E4 -> 0.47058824 | I14: =(C14-F14)+D14 -> 2320 | J14: =G14/F4 -> 0.47058824 | K14: 204500 | L14: =(F14/1000)*K14 -> 16360 | M14: =(G14/1000)*K14 -> 16360 | N14: =L14/E4 -> 96.235294 | O14: =M14/F4 -> 96.235294
A15: 7 | B15: COAGULANT (CL 200) | C15: 1750 | F15: 54 | G15: 54 | H15: =F15/E4 -> 0.31764706 | I15: =(C15-F15)+D15 -> 1696 | J15: =G15/F4 -> 0.31764706 | K15: 129500 | L15: =(F15/1000)*K15 -> 6993 | M15: =(G15/1000)*K15 -> 6993 | N15: =L15/E4 -> 41.135294 | O15: =M15/F4 -> 41.135294
A16: 8 | B16: KROFTA (303) | C16: 985 | F16: 20 | G16: 20 | H16: =F16/E4 -> 0.11764706 | I16: =(C16-F16)+D16 -> 965 | J16: =G16/F4 -> 0.11764706 | K16: 219500 | L16: =(F16/1000)*K16 -> 4390 | M16: =(G16/1000)*K16 -> 4390 | N16: =L16/E4 -> 25.823529 | O16: =M16/F4 -> 25.823529
A17: 9 | B17: BELT PRESS (SUCHEM - 638 ) | C17: 21 | F17: 0 | G17: 0 | H17: =F17/E4 -> 0 | I17: =(C17-F17)+D17 -> 21 | J17: =G17/F4 -> 0 | K17: 348200 | L17: =(F17/1000)*K17 -> 0 | M17: =(G17/1000)*K17 -> 0 | N17: =L17/E4 -> 0 | O17: =M17/F4 -> 0
A18: 10 | B18: GOLDEN YELLOW DYE | C18: 3950 | F18: 0 | G18: 0 | H18: =F18/E4 -> 0 | I18: =(C18-F18)+D18 -> 3950 | J18: =G18/F4 -> 0 | K18: 172000 | L18: =(F18/1000)*K18 -> 0 | M18: =(G18/1000)*K18 -> 0 | N18: =L18/E4 -> 0 | O18: =M18/F4 -> 0
A19: 11 | B19: SE-BOND 102 (CRACKING AGENT) | C19: 48 | F19: 0 | G19: 0 | H19: =F19/E4 -> 0 | I19: =(C19-F19)+D19 -> 48 | J19: =G19/F4 -> 0 | K19: 200000 | L19: =(F19/1000)*K19 -> 0 | M19: =(G19/1000)*K19 -> 0 | N19: =L19/E4 -> 0 | O19: =M19/F4 -> 0
A20: 12 | B20: PROMASK 192 | C20: 163.2 | F20: 6.9 | G20: 6.9 | H20: =F20/E4 -> 0.040588235 | I20: =(C20-F20)+D20 -> 156.3 | J20: =G20/F4 -> 0.040588235 | K20: 377600 | L20: =(F20/1000)*K20 -> 2605.44 | M20: =(G20/1000)*K20 -> 2605.44 | N20: =L20/E4 -> 15.326118 | O20: =M20/F4 -> 15.326118
A21: 13 | B21: PROSOLVE 126 | C21: 134.5 | F21: 4.1 | G21: 4.1 | H21: =F21/E4 -> 0.024117647 | I21: =(C21-F21)+D21 -> 130.4 | J21: =G21/F4 -> 0.024117647 | K21: 271400 | L21: =(F21/1000)*K21 -> 1112.74 | M21: =(G21/1000)*K21 -> 1112.74 | N21: =L21/E4 -> 6.5455294 | O21: =M21/F4 -> 6.5455294
A22: 14 | B22: PROSOLVE ADV. | C22: 1939.2 | F22: 59.3 | G22: 59.3 | H22: =F22/E4 -> 0.34882353 | I22: =(C22-F22)+D22 -> 1879.9 | J22: =G22/F4 -> 0.34882353 | K22: 271400 | L22: =(F22/1000)*K22 -> 16094.02 | M22: =(G22/1000)*K22 -> 16094.02 | N22: =L22/E4 -> 94.670706 | O22: =M22/F4 -> 94.670706
A23: 15 | B23: BLEACHING POWDER (S) | C23: 100 | F23: 0 | G23: 0 | H23: =F23/E4 -> 0 | I23: =(C23-F23)+D23 -> 100 | J23: =G23/F4 -> 0 | K23: 41000 | L23: =(F23/1000)*K23 -> 0 | M23: =(G23/1000)*K23 -> 0 | N23: =L23/E4 -> 0 | O23: =M23/F4 -> 0
A24: 16 | B24: SODIUM HYPO CHLORIDE [HYPO] | C24: 385.6 | F24: 6 | G24: 6 | H24: =F24/E4 -> 0.035294118 | I24: =(C24-F24)+D24 -> 379.6 | J24: =G24/F4 -> 0.035294118 | K24: 24000 | L24: =(F24/1000)*K24 -> 144 | M24: =(G24/1000)*K24 -> 144 | N24: =L24/E4 -> 0.84705882 | O24: =M24/F4 -> 0.84705882
A25: 17 | B25: HCL [PULP MILL] | C25: 380 | F25: 0 | G25: 0 | H25: =F25/E4 -> 0 | I25: =(C25-F25)+D25 -> 380 | J25: =G25/F4 -> 0 | K25: 13210 | L25: =(F25/1000)*K25 -> 0 | M25: =(G25/1000)*K25 -> 0 | N25: =L25/E4 -> 0 | O25: =M25/F4 -> 0
A26: 18 | B26: HCL [BOILER] | C26: 245 | F26: 10 | G26: 10 | H26: =F26/E4 -> 0.058823529 | I26: =(C26-F26)+D26 -> 235 | J26: =G26/F4 -> 0.058823529 | K26: 14400 | L26: =(F26/1000)*K26 -> 144 | M26: =(G26/1000)*K26 -> 144 | N26: =L26/E4 -> 0.84705882 | O26: =M26/F4 -> 0.84705882
A27: 19 | B27: pH BOOSTER [3230] (L) | C27: 205 | F27: 4 | G27: 4 | H27: =F27/E4 -> 0.023529412 | I27: =(C27-F27)+D27 -> 201 | J27: =G27/F4 -> 0.023529412 | K27: 102000 | L27: =(F27/1000)*K27 -> 408 | M27: =(G27/1000)*K27 -> 408 | N27: =L27/E4 -> 2.4 | O27: =M27/F4 -> 2.4
A28: 20 | B28: ANTI SCALEN [3220] (L) | C28: 180 | F28: 5 | G28: 5 | H28: =F28/E4 -> 0.029411765 | I28: =(C28-F28)+D28 -> 175 | J28: =G28/F4 -> 0.029411765 | K28: 107000 | L28: =(F28/1000)*K28 -> 535 | M28: =(G28/1000)*K28 -> 535 | N28: =L28/E4 -> 3.1470588 | O28: =M28/F4 -> 3.1470588
A29: 21 | B29: OXYGEN SCAVANGER [3210] (L) | C29: 169 | F29: 3 | G29: 3 | H29: =F29/E4 -> 0.017647059 | I29: =(C29-F29)+D29 -> 166 | J29: =G29/F4 -> 0.017647059 | K29: 100000 | L29: =(F29/1000)*K29 -> 300 | M29: =(G29/1000)*K29 -> 300 | N29: =L29/E4 -> 1.7647059 | O29: =M29/F4 -> 1.7647059
A30: 22 | B30: RO ANTI SCALEN [3291 (L) | C30: 64 | F30: 1 | G30: 1 | H30: =F30/E4 -> 0.0058823529 | I30: =(C30-F30)+D30 -> 63 | J30: =G30/F4 -> 0.0058823529 | K30: 255000 | L30: =(F30/1000)*K30 -> 255 | M30: =(G30/1000)*K30 -> 255 | N30: =L30/E4 -> 1.5 | O30: =M30/F4 -> 1.5
A31: 23 | B31: CAUSTIC SODA FLAKES | C31: 480 | F31: 0 | G31: 0 | H31: =F31/E4 -> 0 | I31: =(C31-F31)+D31 -> 480 | J31: =G31/F4 -> 0 | K31: 56000 | L31: =(F31/1000)*K31 -> 0 | M31: =(G31/1000)*K31 -> 0 | N31: =M30/F4 -> 1.5 | O31: =M31/F4 -> 0
A32: 24 | B32: DESCALING [3250] (L) | C32: 0 | F32: 0 | G32: 0 | H32: =F32/E4 -> 0 | I32: =(C32-F32)+D32 -> 0 | J32: =G32/F4 -> 0 | K32: 90000 | L32: =(F32/1000)*K32 -> 0 | M32: =(G32/1000)*K32 -> 0 | N32: =M31/F4 -> 0 | O32: =M32/F4 -> 0
A33: S.NO. | B33: QUALITY WISE PRODUCTION | C33: NO. OF SET | D33: PM/C PRODUCTION (MT) | M33: TOTAL | N33: =SUM(N9,N10,N11,N12,N13,N14,N15,N16,N17,N18,N19,N20,N21,N22,N23,N24,N25,N26,N27,N28,N29,N30,N31,N32) -> 1079.9012 | O33: =SUM(O9,O10,O11,O12,O13,O14,O15,O16,O17,O18,O19,O20,O21,O22,O23,O24,O25,O26,O27,O28,O29,N31,N32,O32) -> 1078.4012
A34: 1 | B34: 140 GSM/18 BF (NATURAL) | C34: 33 | F34: 57 | N34: COSTING | O34: COSTING
A35: 2 | B35: 150 GSM/18 BF (NATURAL) | C35: 65 | F35: 113 | N35: TODAY | O35: TO DATE
A36: 3 | N36: Rs./Kg. | O36: Rs./Kg.
A37: 4 | M37: TOTAL | N37: =N33/1000 -> 1.0799012 | O37: =O33/1000 -> 1.0784012
A38: 5
A39: 6
A40: 7
A41: 4 | B41: TOTAL | C41: =SUM(C34,C35,C36,C37,C38,C39,C40) -> 98 | D41: =SUM(F34,F35,F36,F37,F38,F39,F40) -> 170

Sheet 02-07-26
A1: SRI MK PAPER MILLS PVT. LTD.
A3: CHEMICAL CONSUMPTION / BALANCE & COSTING PER DAY & TODATE
A4: PRODUCTION ( MT ) | E4: 149 | F4: 319 | G4: 159.000(AVG) | H4: DATE : 02 - 07 - 2026
A5: PRODUCTION (MT) | C5: GOLDEN YELLOW | E5: 0 | F5: 0 | G5: 000.000(AVG)
A6: SR. | B6: CHEMICAL | C6: OPENING | D6: RECEIVED MATERIAL | F6: CONSUMED MATERIAL | H6: TODAY | I6: CHEMICAL | J6: TO DATE | K6: RATE | L6: TOTAL CONSUMED AMOUNT | N6: COSTING
A7: NO. | B7: NAME | C7: STOCK | D7: TO DAY | E7: TO DATE | F7: TO DAY | G7: TO DATE | H7: CONSUMPTION | I7: BALANCE | J7: CONSUMPTION | K7: RS.@ | L7: TODAY | M7: TO DATE | N7: TODAY | O7: TO DATE
C8: (Kgs.) | D8: (Kgs.) | E8: (Kgs.) | F8: (Kgs.) | G8: (Kgs.) | H8: (Kgs.)/MTP | I8: (Kgs.) | J8: (Kgs.)/MTP | K8: MT | L8: Rs. | M8: Rs. | N8: Rs./MTP | O8: Rs./MTP
A9: 1 | B9: STARCH | C9: 9500 | D9: 13000 | E9: 13000 | F9: 3950 | G9: ='01-07-26'!F9+'02-07-26'!F9 -> 7850 | H9: =F9/E4 -> 26.510067 | I9: =(C9-F9)+D9 -> 18550 | J9: =G9/F4 -> 24.60815 | K9: 28500 | L9: =(F9/1000)*K9 -> 112575 | M9: =(G9/1000)*K9 -> 223725 | N9: =L9/E4 -> 755.53691 | O9: =M9/F4 -> 701.33229
A10: 2 | B10: PAC ( SOLID) | C10: 8778 | F10: 190 | G10: ='01-07-26'!F10+'02-07-26'!F10 -> 412 | H10: =F10/E4 -> 1.2751678 | I10: =(C10-F10)+D10 -> 8588 | J10: =G10/F4 -> 1.2915361 | K10: 35500 | L10: =(F10/1000)*K10 -> 6745 | M10: =(G10/1000)*K10 -> 14626 | N10: =L10/E4 -> 45.268456 | O10: =M10/F4 -> 45.84953
A11: 3 | B11: SURFACE SIZE (700C) | C11: 6743 | F11: 60 | G11: ='01-07-26'!F11+'02-07-26'!F11 -> 137 | H11: =F11/E4 -> 0.40268456 | I11: =(C11-F11)+D11 -> 6683 | J11: =G11/F4 -> 0.42946708 | K11: 98000 | L11: =(F11/1000)*K11 -> 5880 | M11: =(G11/1000)*K11 -> 13426 | N11: =L11/E4 -> 39.463087 | O11: =M11/F4 -> 42.087774
A12: 4 | B12: ENZYME (L) | C12: 20.92 | F12: 0.08 | G12: ='01-07-26'!F12+'02-07-26'!F12 -> 0.16 | H12: =F12/E4 -> 0.00053691275 | I12: =(C12-F12)+D12 -> 20.84 | J12: =G12/F4 -> 0.0005015674 | K12: 750000 | L12: =(F12/1000)*K12 -> 60 | M12: =(G12/1000)*K12 -> 120 | N12: =L12/E4 -> 0.40268456 | O12: =M12/F4 -> 0.37617555
A13: 5 | B13: RETENTION AID (2024) | C13: 479 | F13: 22 | G13: ='01-07-26'!F13+'02-07-26'!F13 -> 43 | H13: =F13/E4 -> 0.14765101 | I13: =(C13-F13)+D13 -> 457 | J13: =G13/F4 -> 0.13479624 | K13: 350000 | L13: =(F13/1000)*K13 -> 7700 | M13: =(G13/1000)*K13 -> 15050 | N13: =L13/E4 -> 51.677852 | O13: =M13/F4 -> 47.178683
A14: 6 | B14: DEFOAMER (SE 100) | C14: 2320 | F14: 60 | G14: ='01-07-26'!F14+'02-07-26'!F14 -> 140 | H14: =F14/E4 -> 0.40268456 | I14: =(C14-F14)+D14 -> 2260 | J14: =G14/F4 -> 0.43887147 | K14: 204500 | L14: =(F14/1000)*K14 -> 12270 | M14: =(G14/1000)*K14 -> 28630 | N14: =L14/E4 -> 82.348993 | O14: =M14/F4 -> 89.749216
A15: 7 | B15: COAGULANT (CL 200) | C15: 1696 | F15: 54 | G15: ='01-07-26'!F15+'02-07-26'!F15 -> 108 | H15: =F15/E4 -> 0.36241611 | I15: =(C15-F15)+D15 -> 1642 | J15: =G15/F4 -> 0.33855799 | K15: 129500 | L15: =(F15/1000)*K15 -> 6993 | M15: =(G15/1000)*K15 -> 13986 | N15: =L15/E4 -> 46.932886 | O15: =M15/F4 -> 43.84326
A16: 8 | B16: KROFTA (303) | C16: 965 | F16: 15 | G16: ='01-07-26'!F16+'02-07-26'!F16 -> 35 | H16: =F16/E4 -> 0.10067114 | I16: =(C16-F16)+D16 -> 950 | J16: =G16/F4 -> 0.10971787 | K16: 219500 | L16: =(F16/1000)*K16 -> 3292.5 | M16: =(G16/1000)*K16 -> 7682.5 | N16: =L16/E4 -> 22.097315 | O16: =M16/F4 -> 24.083072
A17: 9 | B17: BELT PRESS (SUCHEM - 638 ) | C17: 21 | F17: 0 | G17: ='01-07-26'!F17+'02-07-26'!F17 -> 0 | H17: =F17/E4 -> 0 | I17: =(C17-F17)+D17 -> 21 | J17: =G17/F4 -> 0 | K17: 348200 | L17: =(F17/1000)*K17 -> 0 | M17: =(G17/1000)*K17 -> 0 | N17: =L17/E4 -> 0 | O17: =M17/F4 -> 0
A18: 10 | B18: GOLDEN YELLOW DYE | C18: 3950 | F18: 0 | G18: ='01-07-26'!F18+'02-07-26'!F18 -> 0 | H18: =F18/E4 -> 0 | I18: =(C18-F18)+D18 -> 3950 | J18: =G18/F4 -> 0 | K18: 172000 | L18: =(F18/1000)*K18 -> 0 | M18: =(G18/1000)*K18 -> 0 | N18: =L18/E4 -> 0 | O18: =M18/F4 -> 0
A19: 11 | B19: SE-BOND 102 (CRACKING AGENT) | C19: 48 | F19: 0 | G19: ='01-07-26'!F19+'02-07-26'!F19 -> 0 | H19: =F19/E4 -> 0 | I19: =(C19-F19)+D19 -> 48 | J19: =G19/F4 -> 0 | K19: 200000 | L19: =(F19/1000)*K19 -> 0 | M19: =(G19/1000)*K19 -> 0 | N19: =L19/E4 -> 0 | O19: =M19/F4 -> 0
A20: 12 | B20: PROMASK 192 | C20: 156.3 | F20: 5.5 | G20: ='01-07-26'!F20+'02-07-26'!F20 -> 12.4 | H20: =F20/E4 -> 0.036912752 | I20: =(C20-F20)+D20 -> 150.8 | J20: =G20/F4 -> 0.038871473 | K20: 377600 | L20: =(F20/1000)*K20 -> 2076.8 | M20: =(G20/1000)*K20 -> 4682.24 | N20: =L20/E4 -> 13.938255 | O20: =M20/F4 -> 14.677868
A21: 13 | B21: PROSOLVE 126 | C21: 130.4 | F21: 3.3 | G21: ='01-07-26'!F21+'02-07-26'!F21 -> 7.4 | H21: =F21/E4 -> 0.022147651 | I21: =(C21-F21)+D21 -> 127.1 | J21: =G21/F4 -> 0.023197492 | K21: 271400 | L21: =(F21/1000)*K21 -> 895.62 | M21: =(G21/1000)*K21 -> 2008.36 | N21: =L21/E4 -> 6.0108725 | O21: =M21/F4 -> 6.2957994
A22: 14 | B22: PROSOLVE ADV. | C22: 1879.9 | F22: 47.4 | G22: ='01-07-26'!F22+'02-07-26'!F22 -> 106.7 | H22: =F22/E4 -> 0.31812081 | I22: =(C22-F22)+D22 -> 1832.5 | J22: =G22/F4 -> 0.33448276 | K22: 271400 | L22: =(F22/1000)*K22 -> 12864.36 | M22: =(G22/1000)*K22 -> 28958.38 | N22: =L22/E4 -> 86.337987 | O22: =M22/F4 -> 90.778621
A23: 15 | B23: BLEACHING POWDER (S) | C23: 100 | F23: 0 | G23: ='01-07-26'!F23+'02-07-26'!F23 -> 0 | H23: =F23/E4 -> 0 | I23: =(C23-F23)+D23 -> 100 | J23: =G23/F4 -> 0 | K23: 41000 | L23: =(F23/1000)*K23 -> 0 | M23: =(G23/1000)*K23 -> 0 | N23: =L23/E4 -> 0 | O23: =M23/F4 -> 0
A24: 16 | B24: SODIUM HYPO CHLORIDE [HYPO] | C24: 379.6 | F24: 6 | G24: ='01-07-26'!F24+'02-07-26'!F24 -> 12 | H24: =F24/E4 -> 0.040268456 | I24: =(C24-F24)+D24 -> 373.6 | J24: =G24/F4 -> 0.037617555 | K24: 24000 | L24: =(F24/1000)*K24 -> 144 | M24: =(G24/1000)*K24 -> 288 | N24: =L24/E4 -> 0.96644295 | O24: =M24/F4 -> 0.90282132
A25: 17 | B25: HCL [PULP MILL] | C25: 380 | F25: 0 | G25: ='01-07-26'!F25+'02-07-26'!F25 -> 0 | H25: =F25/E4 -> 0 | I25: =(C25-F25)+D25 -> 380 | J25: =G25/F4 -> 0 | K25: 13210 | L25: =(F25/1000)*K25 -> 0 | M25: =(G25/1000)*K25 -> 0 | N25: =L25/E4 -> 0 | O25: =M25/F4 -> 0
A26: 18 | B26: HCL [BOILER] | C26: 235 | F26: 10 | G26: ='01-07-26'!F26+'02-07-26'!F26 -> 20 | H26: =F26/E4 -> 0.067114094 | I26: =(C26-F26)+D26 -> 225 | J26: =G26/F4 -> 0.062695925 | K26: 14400 | L26: =(F26/1000)*K26 -> 144 | M26: =(G26/1000)*K26 -> 288 | N26: =L26/E4 -> 0.96644295 | O26: =M26/F4 -> 0.90282132
A27: 19 | B27: pH BOOSTER [3230] (L) | C27: 201 | F27: 3.5 | G27: ='01-07-26'!F27+'02-07-26'!F27 -> 7.5 | H27: =F27/E4 -> 0.023489933 | I27: =(C27-F27)+D27 -> 197.5 | J27: =G27/F4 -> 0.023510972 | K27: 102000 | L27: =(F27/1000)*K27 -> 357 | M27: =(G27/1000)*K27 -> 765 | N27: =L27/E4 -> 2.3959732 | O27: =M27/F4 -> 2.3981191
A28: 20 | B28: ANTI SCALEN [3220] (L) | C28: 175 | F28: 5 | G28: ='01-07-26'!F28+'02-07-26'!F28 -> 10 | H28: =F28/E4 -> 0.033557047 | I28: =(C28-F28)+D28 -> 170 | J28: =G28/F4 -> 0.031347962 | K28: 107000 | L28: =(F28/1000)*K28 -> 535 | M28: =(G28/1000)*K28 -> 1070 | N28: =L28/E4 -> 3.590604 | O28: =M28/F4 -> 3.354232
A29: 21 | B29: OXYGEN SCAVANGER [3210] (L) | C29: 166 | F29: 3 | G29: ='01-07-26'!F29+'02-07-26'!F29 -> 6 | H29: =F29/E4 -> 0.020134228 | I29: =(C29-F29)+D29 -> 163 | J29: =G29/F4 -> 0.018808777 | K29: 100000 | L29: =(F29/1000)*K29 -> 300 | M29: =(G29/1000)*K29 -> 600 | N29: =L29/E4 -> 2.0134228 | O29: =M29/F4 -> 1.8808777
A30: 22 | B30: RO ANTI SCALEN [3291 (L) | C30: 63 | F30: 1 | G30: ='01-07-26'!F30+'02-07-26'!F30 -> 2 | H30: =F30/E4 -> 0.0067114094 | I30: =(C30-F30)+D30 -> 62 | J30: =G30/F4 -> 0.0062695925 | K30: 255000 | L30: =(F30/1000)*K30 -> 255 | M30: =(G30/1000)*K30 -> 510 | N30: =L30/E4 -> 1.7114094 | O30: =M30/F4 -> 1.5987461
A31: 23 | B31: CAUSTIC SODA FLAKES | C31: 480 | F31: 0 | G31: ='01-07-26'!F31+'02-07-26'!F31 -> 0 | H31: =F31/E4 -> 0 | I31: =(C31-F31)+D31 -> 480 | J31: =G31/F4 -> 0 | K31: 56000 | L31: =(F31/1000)*K31 -> 0 | M31: =(G31/1000)*K31 -> 0 | N31: =M30/F4 -> 1.5987461 | O31: =M31/F4 -> 0
A32: 24 | B32: DESCALING [3250] (L) | C32: 0 | F32: 0 | G32: ='01-07-26'!F32+'02-07-26'!F32 -> 0 | H32: =F32/E4 -> 0 | I32: =(C32-F32)+D32 -> 0 | J32: =G32/F4 -> 0 | K32: 90000 | L32: =(F32/1000)*K32 -> 0 | M32: =(G32/1000)*K32 -> 0 | N32: =M31/F4 -> 0 | O32: =M32/F4 -> 0
A33: S.NO. | B33: QUALITY WISE PRODUCTION | C33: NO. OF SET | D33: PM/C PRODUCTION (MT) | M33: TOTAL | N33: =SUM(N9,N10,N11,N12,N13,N14,N15,N16,N17,N18,N19,N20,N21,N22,N23,N24,N25,N26,N27,N28,N29,N30,N31,N32) -> 1163.2583 | O33: =SUM(O9,O10,O11,O12,O13,O14,O15,O16,O17,O18,O19,O20,O21,O22,O23,O24,O25,O26,O27,O28,O29,N31,N32,O32) -> 1117.2899
A34: 1 | B34: 180 GSM/18 BF (NATURAL) | C34: 58 | F34: =C34*E4/C41 -> 97.101124 | N34: COSTING | O34: COSTING
A35: 2 | B35: 150 GSM/18 BF (NATURAL) | C35: 29 | F35: =C35*E4/C41 -> 48.550562 | N35: TODAY | O35: TO DATE
A36: 3 | B36: 180 GSM/20 BF (NATURAL) | C36: 2 | F36: =C36*E4/C41 -> 3.3483146 | N36: Rs./Kg. | O36: Rs./Kg.
A37: 4 | M37: TOTAL | N37: =N33/1000 -> 1.1632583 | O37: =O33/1000 -> 1.1172899
A38: 5
A39: 6
A40: 7
A41: 4 | B41: TOTAL | C41: =SUM(C34,C35,C36,C37,C38,C39,C40) -> 89 | D41: =SUM(F34,F35,F36,F37,F38,F39,F40) -> 149

Sheet 03-07-26
A1: SRI MK PAPER MILLS PVT. LTD.
A3: CHEMICAL CONSUMPTION / BALANCE & COSTING PER DAY & TODATE
A4: PRODUCTION ( MT ) | E4: 163 | F4: 482 | G4: 160.6 | H4: DATE : 03 - 07 - 2026
A5: PRODUCTION (MT) | C5: GOLDEN YELLOW | E5: 0 | F5: 0 | G5: 000.000(AVG)
A6: SR. | B6: CHEMICAL | C6: OPENING | D6: RECEIVED MATERIAL | F6: CONSUMED MATERIAL | H6: TODAY | I6: CHEMICAL | J6: TO DATE | K6: RATE | L6: TOTAL CONSUMED AMOUNT | N6: COSTING
A7: NO. | B7: NAME | C7: STOCK | D7: TO DAY | E7: TO DATE | F7: TO DAY | G7: TO DATE | H7: CONSUMPTION | I7: BALANCE | J7: CONSUMPTION | K7: RS.@ | L7: TODAY | M7: TO DATE | N7: TODAY | O7: TO DATE
C8: (Kgs.) | D8: (Kgs.) | E8: (Kgs.) | F8: (Kgs.) | G8: (Kgs.) | H8: (Kgs.)/MTP | I8: (Kgs.) | J8: (Kgs.)/MTP | K8: MT | L8: Rs. | M8: Rs. | N8: Rs./MTP | O8: Rs./MTP
A9: 1 | B9: STARCH | C9: 18550 | D9: 0 | E9: 13000 | F9: 5800 | G9: ='02-07-26'!G9+'03-07-26'!F9 -> 13650 | H9: =F9/E4 -> 35.582822 | I9: =(C9-F9)+D9 -> 12750 | J9: =G9/F4 -> 28.319502 | K9: 28500 | L9: =(F9/1000)*K9 -> 165300 | M9: =(G9/1000)*K9 -> 389025 | N9: =L9/E4 -> 1014.1104 | O9: =M9/F4 -> 807.10581
A10: 2 | B10: PAC ( SOLID) | C10: 8588 | F10: 238 | G10: ='02-07-26'!G10+'03-07-26'!F10 -> 650 | H10: =F10/E4 -> 1.4601227 | I10: =(C10-F10)+D10 -> 8350 | J10: =G10/F4 -> 1.3485477 | K10: 35500 | L10: =(F10/1000)*K10 -> 8449 | M10: =(G31/1000)*K10 -> 0 | N10: =L10/E4 -> 51.834356 | O10: =M10/F4 -> 0
A11: 3 | B11: SURFACE SIZE (700C) | C11: 6683 | F11: 69 | G11: ='02-07-26'!G11+'03-07-26'!F11 -> 206 | H11: =F11/E4 -> 0.42331288 | I11: =(C11-F11)+D11 -> 6614 | J11: =G11/F4 -> 0.42738589 | K11: 98000 | L11: =(F11/1000)*K11 -> 6762 | M11: =(G11/1000)*K11 -> 20188 | N11: =L11/E4 -> 41.484663 | O11: =M11/F4 -> 41.883817
A12: 4 | B12: ENZYME (L) | C12: 20.84 | F12: 0.08 | G12: ='02-07-26'!G12+'03-07-26'!F12 -> 0.24 | H12: =F12/E4 -> 0.00049079755 | I12: =(C12-F12)+D12 -> 20.76 | J12: =G12/F4 -> 0.00049792531 | K12: 750000 | L12: =(F12/1000)*K12 -> 60 | M12: =(G12/1000)*K12 -> 180 | N12: =L12/E4 -> 0.36809816 | O12: =M12/F4 -> 0.37344398
A13: 5 | B13: RETENTION AID (2024) | C13: 457 | F13: 20 | G13: ='02-07-26'!G13+'03-07-26'!F13 -> 63 | H13: =F13/E4 -> 0.12269939 | I13: =(C13-F13)+D13 -> 437 | J13: =G13/F4 -> 0.13070539 | K13: 350000 | L13: =(F13/1000)*K13 -> 7000 | M13: =(G13/1000)*K13 -> 22050 | N13: =L13/E4 -> 42.944785 | O13: =M13/F4 -> 45.746888
A14: 6 | B14: DEFOAMER (SE 100) | C14: 2260 | F14: 45 | G14: ='02-07-26'!G14+'03-07-26'!F14 -> 185 | H14: =F14/E4 -> 0.27607362 | I14: =(C14-F14)+D14 -> 2215 | J14: =G14/F4 -> 0.38381743 | K14: 204500 | L14: =(F14/1000)*K14 -> 9202.5 | M14: =(G14/1000)*K14 -> 37832.5 | N14: =L14/E4 -> 56.457055 | O14: =M14/F4 -> 78.490664
A15: 7 | B15: COAGULANT (CL 200) | C15: 1642 | F15: 59 | G15: ='02-07-26'!G15+'03-07-26'!F15 -> 167 | H15: =F15/E4 -> 0.36196319 | I15: =(C15-F15)+D15 -> 1583 | J15: =G15/F4 -> 0.34647303 | K15: 129500 | L15: =(F15/1000)*K15 -> 7640.5 | M15: =(G15/1000)*K15 -> 21626.5 | N15: =L15/E4 -> 46.874233 | O15: =M15/F4 -> 44.868257
A16: 8 | B16: KROFTA (303) | C16: 950 | F16: 15 | G16: ='02-07-26'!G16+'03-07-26'!F16 -> 50 | H16: =F16/E4 -> 0.09202454 | I16: =(C16-F16)+D16 -> 935 | J16: =G16/F4 -> 0.10373444 | K16: 219500 | L16: =(F16/1000)*K16 -> 3292.5 | M16: =(G16/1000)*K16 -> 10975 | N16: =L16/E4 -> 20.199387 | O16: =M16/F4 -> 22.76971
A17: 9 | B17: BELT PRESS (SUCHEM - 638 ) | C17: 21 | F17: 0 | G17: ='02-07-26'!G17+'03-07-26'!F17 -> 0 | H17: =F17/E4 -> 0 | I17: =(C17-F17)+D17 -> 21 | J17: =G17/F4 -> 0 | K17: 348200 | L17: =(F17/1000)*K17 -> 0 | M17: =(G17/1000)*K17 -> 0 | N17: =L17/E4 -> 0 | O17: =M17/F4 -> 0
A18: 10 | B18: GOLDEN YELLOW DYE | C18: 3950 | F18: 0 | G18: ='02-07-26'!G18+'03-07-26'!F18 -> 0 | H18: =F18/E4 -> 0 | I18: =(C18-F18)+D18 -> 3950 | J18: =G18/F4 -> 0 | K18: 172000 | L18: =(F18/1000)*K18 -> 0 | M18: =(G18/1000)*K18 -> 0 | N18: =L18/E4 -> 0 | O18: =M18/F4 -> 0
A19: 11 | B19: SE-BOND 102 (CRACKING AGENT) | C19: 48 | F19: 0 | G19: ='02-07-26'!G19+'03-07-26'!F19 -> 0 | H19: =F19/E4 -> 0 | I19: =(C19-F19)+D19 -> 48 | J19: =G19/F4 -> 0 | K19: 200000 | L19: =(F19/1000)*K19 -> 0 | M19: =(G19/1000)*K19 -> 0 | N19: =L19/E4 -> 0 | O19: =M19/F4 -> 0
A20: 12 | B20: PROMASK 192 | C20: 150.8 | F20: 7.2 | G20: ='02-07-26'!G20+'03-07-26'!F20 -> 19.6 | H20: =F20/E4 -> 0.044171779 | I20: =(C20-F20)+D20 -> 143.6 | J20: =G20/F4 -> 0.0406639 | K20: 377600 | L20: =(F20/1000)*K20 -> 2718.72 | M20: =(G20/1000)*K20 -> 7400.96 | N20: =L20/E4 -> 16.679264 | O20: =M20/F4 -> 15.354689
A21: 13 | B21: PROSOLVE 126 | C21: 127.1 | F21: 4.3 | G21: ='02-07-26'!G21+'03-07-26'!F21 -> 11.7 | H21: =F21/E4 -> 0.026380368 | I21: =(C21-F21)+D21 -> 122.8 | J21: =G21/F4 -> 0.024273859 | K21: 271400 | L21: =(F21/1000)*K21 -> 1167.02 | M21: =(G21/1000)*K21 -> 3175.38 | N21: =L21/E4 -> 7.1596319 | O21: =M21/F4 -> 6.5879253
A22: 14 | B22: PROSOLVE ADV. | C22: 1832.5 | F22: 61.9 | G22: ='02-07-26'!G22+'03-07-26'!F22 -> 168.6 | H22: =F22/E4 -> 0.3797546 | I22: =(C22-F22)+D22 -> 1770.6 | J22: =G22/F4 -> 0.34979253 | K22: 271400 | L22: =(F22/1000)*K22 -> 16799.66 | M22: =(G22/1000)*K22 -> 45758.04 | N22: =L22/E4 -> 103.0654 | O22: =M22/F4 -> 94.933693
A23: 15 | B23: BLEACHING POWDER (S) | C23: 100 | F23: 0 | G23: ='02-07-26'!G23+'03-07-26'!F23 -> 0 | H23: =F23/E4 -> 0 | I23: =(C23-F23)+D23 -> 100 | J23: =G23/F4 -> 0 | K23: 41000 | L23: =(F23/1000)*K23 -> 0 | M23: =(G23/1000)*K23 -> 0 | N23: =L23/E4 -> 0 | O23: =M23/F4 -> 0
A24: 16 | B24: SODIUM HYPO CHLORIDE [HYPO] | C24: 379.6 | F24: 6 | G24: ='02-07-26'!G24+'03-07-26'!F24 -> 18 | H24: =F24/E4 -> 0.036809816 | I24: =(C24-F24)+D24 -> 373.6 | J24: =G24/F4 -> 0.037344398 | K24: 24000 | L24: =(F24/1000)*K24 -> 144 | M24: =(G24/1000)*K24 -> 432 | N24: =L24/E4 -> 0.88343558 | O24: =M24/F4 -> 0.89626556
A25: 17 | B25: HCL [PULP MILL] | C25: 380 | F25: 0 | G25: ='02-07-26'!G25+'03-07-26'!F25 -> 0 | H25: =F25/E4 -> 0 | I25: =(C25-F25)+D25 -> 380 | J25: =G25/F4 -> 0 | K25: 13210 | L25: =(F25/1000)*K25 -> 0 | M25: =(G25/1000)*K25 -> 0 | N25: =L25/E4 -> 0 | O25: =M25/F4 -> 0
A26: 18 | B26: HCL [BOILER] | C26: 225 | F26: 10 | G26: ='02-07-26'!G26+'03-07-26'!F26 -> 30 | H26: =F26/E4 -> 0.061349693 | I26: =(C26-F26)+D26 -> 215 | J26: =G26/F4 -> 0.062240664 | K26: 14400 | L26: =(F26/1000)*K26 -> 144 | M26: =(G26/1000)*K26 -> 432 | N26: =L26/E4 -> 0.88343558 | O26: =M26/F4 -> 0.89626556
A27: 19 | B27: pH BOOSTER [3230] (L) | C27: 197.5 | F27: 3.5 | G27: ='02-07-26'!G27+'03-07-26'!F27 -> 11 | H27: =F27/E4 -> 0.021472393 | I27: =(C27-F27)+D27 -> 194 | J27: =G27/F4 -> 0.022821577 | K27: 102000 | L27: =(F27/1000)*K27 -> 357 | M27: =(G27/1000)*K27 -> 1122 | N27: =L27/E4 -> 2.190184 | O27: =M27/F4 -> 2.3278008
A28: 20 | B28: ANTI SCALEN [3220] (L) | C28: 170 | F28: 5 | G28: ='02-07-26'!G28+'03-07-26'!F28 -> 15 | H28: =F28/E4 -> 0.030674847 | I28: =(C28-F28)+D28 -> 165 | J28: =G28/F4 -> 0.031120332 | K28: 107000 | L28: =(F28/1000)*K28 -> 535 | M28: =(G28/1000)*K28 -> 1605 | N28: =L28/E4 -> 3.2822086 | O28: =M28/F4 -> 3.3298755
A29: 21 | B29: OXYGEN SCAVANGER [3210] (L) | C29: 163 | F29: 3 | G29: ='02-07-26'!G29+'03-07-26'!F29 -> 9 | H29: =F29/E4 -> 0.018404908 | I29: =(C29-F29)+D29 -> 160 | J29: =G29/F4 -> 0.018672199 | K29: 100000 | L29: =(F29/1000)*K29 -> 300 | M29: =(G29/1000)*K29 -> 900 | N29: =L29/E4 -> 1.8404908 | O29: =M29/F4 -> 1.8672199
A30: 22 | B30: RO ANTI SCALEN [3291 (L) | C30: 62 | F30: 1 | G30: ='02-07-26'!G30+'03-07-26'!F30 -> 3 | H30: =F30/E4 -> 0.0061349693 | I30: =(C30-F30)+D30 -> 61 | J30: =G30/F4 -> 0.0062240664 | K30: 255000 | L30: =(F30/1000)*K30 -> 255 | M30: =(G30/1000)*K30 -> 765 | N30: =L30/E4 -> 1.5644172 | O30: =M30/F4 -> 1.5871369
A31: 23 | B31: CAUSTIC SODA FLAKES | C31: 480 | F31: 0 | G31: ='02-07-26'!G31+'03-07-26'!F31 -> 0 | H31: =F31/E4 -> 0 | I31: =(C31-F31)+D31 -> 480 | J31: =G31/F4 -> 0 | K31: 56000 | L31: =(F31/1000)*K31 -> 0 | M31: =(G31/1000)*K31 -> 0 | N31: =M30/F4 -> 1.5871369 | O31: =M31/F4 -> 0
A32: 24 | B32: DESCALING [3250] (L) | C32: 0 | F32: 0 | G32: ='02-07-26'!G32+'03-07-26'!F32 -> 0 | H32: =F32/E4 -> 0 | I32: =(C32-F32)+D32 -> 0 | J32: =G32/F4 -> 0 | K32: 90000 | L32: =(F32/1000)*K32 -> 0 | M32: =(G32/1000)*K32 -> 0 | N32: =M31/F4 -> 0 | O32: =M32/F4 -> 0
A33: S.NO. | B33: QUALITY WISE PRODUCTION | C33: NO. OF SET | D33: PM/C PRODUCTION (MT) | M33: TOTAL | N33: =SUM(N9:N32) -> 1413.4086 | O33: =SUM(O9:O32) -> 1169.0195
A34: 1 | B34: 180 GSM/22 BF (NATURAL) | C34: 26 | F34: =C34*E4/C41 -> 44.145833 | N34: COSTING | O34: COSTING
A35: 2 | B35: 140 GSM/20 BF (NATURAL) | C35: 31 | F35: =C35*E4/C41 -> 52.635417 | N35: TODAY | O35: TO DATE
A36: 3 | B36: 180 GSM/20 BF (NATURAL) | C36: 1 | F36: =C36*E4/C41 -> 1.6979167 | N36: Rs./Kg. | O36: Rs./Kg.
A37: 4 | B37: 120 GSM/20 BF (NATURAL) | C37: 38 | F37: =C37*E4/C41 -> 64.520833 | M37: TOTAL | N37: =N33/1000 -> 1.4134086 | O37: =O33/1000 -> 1.1690195
A38: 5
A39: 6
A40: 7
A41: 4 | B41: TOTAL | C41: =SUM(C34,C35,C36,C37,C38,C39,C40) -> 96 | D41: =SUM(F34,F35,F36,F37,F38,F39,F40) -> 163

Sheet 04-07-26
A1: SRI MK PAPER MILLS PVT. LTD.
A3: CHEMICAL CONSUMPTION / BALANCE & COSTING PER DAY & TODATE
A4: PRODUCTION ( MT ) | E4: 59 | F4: 541 | G4: 135.25 | H4: DATE : 04 - 07 - 2026
A5: PRODUCTION (MT) | C5: GOLDEN YELLOW | E5: 0 | F5: 0 | G5: 000.000(AVG)
A6: SR. | B6: CHEMICAL | C6: OPENING | D6: RECEIVED MATERIAL | F6: CONSUMED MATERIAL | H6: TODAY | I6: CHEMICAL | J6: TO DATE | K6: RATE | L6: TOTAL CONSUMED AMOUNT | N6: COSTING
A7: NO. | B7: NAME | C7: STOCK | D7: TO DAY | E7: TO DATE | F7: TO DAY | G7: TO DATE | H7: CONSUMPTION | I7: BALANCE | J7: CONSUMPTION | K7: RS.@ | L7: TODAY | M7: TO DATE | N7: TODAY | O7: TO DATE
C8: (Kgs.) | D8: (Kgs.) | E8: (Kgs.) | F8: (Kgs.) | G8: (Kgs.) | H8: (Kgs.)/MTP | I8: (Kgs.) | J8: (Kgs.)/MTP | K8: MT | L8: Rs. | M8: Rs. | N8: Rs./MTP | O8: Rs./MTP
A9: 1 | B9: STARCH | C9: 12750 | D9: 0 | E9: 13000 | F9: 1400 | G9: ='03-07-26'!G9+'04-07-26'!F9 -> 15050 | H9: =F9/E4 -> 23.728814 | I9: =(C9-F9)+D9 -> 11350 | J9: =G9/F4 -> 27.818854 | K9: 28500 | L9: =(F9/1000)*K9 -> 39900 | M9: =(G9/1000)*K9 -> 428925 | N9: =L9/E4 -> 676.27119 | O9: =M9/F4 -> 792.83734
A10: 2 | B10: PAC ( SOLID) | C10: 8350 | F10: 110 | G10: ='03-07-26'!G10+'04-07-26'!F10 -> 760 | H10: =F10/E4 -> 1.8644068 | I10: =(C10-F10)+D10 -> 8240 | J10: =G10/F4 -> 1.4048059 | K10: 35500 | L10: =(F10/1000)*K10 -> 3905 | M10: =(G31/1000)*K10 -> 0 | N10: =L10/E4 -> 66.186441 | O10: =M10/F4 -> 0
A11: 3 | B11: SURFACE SIZE (700C) | C11: 6614 | F11: 23 | G11: ='03-07-26'!G11+'04-07-26'!F11 -> 229 | H11: =F11/E4 -> 0.38983051 | I11: =(C11-F11)+D11 -> 6591 | J11: =G11/F4 -> 0.4232902 | K11: 98000 | L11: =(F11/1000)*K11 -> 2254 | M11: =(G11/1000)*K11 -> 22442 | N11: =L11/E4 -> 38.20339 | O11: =M11/F4 -> 41.48244
A12: 4 | B12: ENZYME (L) | C12: 20.76 | F12: 0.08 | G12: ='03-07-26'!G12+'04-07-26'!F12 -> 0.32 | H12: =F12/E4 -> 0.0013559322 | I12: =(C12-F12)+D12 -> 20.68 | J12: =G12/F4 -> 0.00059149723 | K12: 750000 | L12: =(F12/1000)*K12 -> 60 | M12: =(G12/1000)*K12 -> 240 | N12: =L12/E4 -> 1.0169492 | O12: =M12/F4 -> 0.44362292
A13: 5 | B13: RETENTION AID (2024) | C13: 437 | F13: 12 | G13: ='03-07-26'!G13+'04-07-26'!F13 -> 75 | H13: =F13/E4 -> 0.20338983 | I13: =(C13-F13)+D13 -> 425 | J13: =G13/F4 -> 0.13863216 | K13: 350000 | L13: =(F13/1000)*K13 -> 4200 | M13: =(G13/1000)*K13 -> 26250 | N13: =L13/E4 -> 71.186441 | O13: =M13/F4 -> 48.521257
A14: 6 | B14: DEFOAMER (SE 100) | C14: 2215 | F14: 20 | G14: ='03-07-26'!G14+'04-07-26'!F14 -> 205 | H14: =F14/E4 -> 0.33898305 | I14: =(C14-F14)+D14 -> 2195 | J14: =G14/F4 -> 0.37892791 | K14: 204500 | L14: =(F14/1000)*K14 -> 4090 | M14: =(G14/1000)*K14 -> 41922.5 | N14: =L14/E4 -> 69.322034 | O14: =M14/F4 -> 77.490758
A15: 7 | B15: COAGULANT (CL 200) | C15: 1583 | F15: 20 | G15: ='03-07-26'!G15+'04-07-26'!F15 -> 187 | H15: =F15/E4 -> 0.33898305 | I15: =(C15-F15)+D15 -> 1563 | J15: =G15/F4 -> 0.34565619 | K15: 129500 | L15: =(F15/1000)*K15 -> 2590 | M15: =(G15/1000)*K15 -> 24216.5 | N15: =L15/E4 -> 43.898305 | O15: =M15/F4 -> 44.762477
A16: 8 | B16: KROFTA (303) | C16: 935 | F16: 15 | G16: ='03-07-26'!G16+'04-07-26'!F16 -> 65 | H16: =F16/E4 -> 0.25423729 | I16: =(C16-F16)+D16 -> 920 | J16: =G16/F4 -> 0.12014787 | K16: 219500 | L16: =(F16/1000)*K16 -> 3292.5 | M16: =(G16/1000)*K16 -> 14267.5 | N16: =L16/E4 -> 55.805085 | O16: =M16/F4 -> 26.372458
A17: 9 | B17: BELT PRESS (SUCHEM - 638 ) | C17: 21 | F17: 0 | G17: ='03-07-26'!G17+'04-07-26'!F17 -> 0 | H17: =F17/E4 -> 0 | I17: =(C17-F17)+D17 -> 21 | J17: =G17/F4 -> 0 | K17: 348200 | L17: =(F17/1000)*K17 -> 0 | M17: =(G17/1000)*K17 -> 0 | N17: =L17/E4 -> 0 | O17: =M17/F4 -> 0
A18: 10 | B18: GOLDEN YELLOW DYE | C18: 3950 | F18: 0 | G18: ='03-07-26'!G18+'04-07-26'!F18 -> 0 | H18: =F18/E4 -> 0 | I18: =(C18-F18)+D18 -> 3950 | J18: =G18/F4 -> 0 | K18: 172000 | L18: =(F18/1000)*K18 -> 0 | M18: =(G18/1000)*K18 -> 0 | N18: =L18/E4 -> 0 | O18: =M18/F4 -> 0
A19: 11 | B19: SE-BOND 102 (CRACKING AGENT) | C19: 48 | F19: 0 | G19: ='03-07-26'!G19+'04-07-26'!F19 -> 0 | H19: =F19/E4 -> 0 | I19: =(C19-F19)+D19 -> 48 | J19: =G19/F4 -> 0 | K19: 200000 | L19: =(F19/1000)*K19 -> 0 | M19: =(G19/1000)*K19 -> 0 | N19: =L19/E4 -> 0 | O19: =M19/F4 -> 0
A20: 12 | B20: PROMASK 192 | C20: 143.6 | F20: 3 | G20: ='03-07-26'!G20+'04-07-26'!F20 -> 22.6 | H20: =F20/E4 -> 0.050847458 | I20: =(C20-F20)+D20 -> 140.6 | J20: =G20/F4 -> 0.041774492 | K20: 377600 | L20: =(F20/1000)*K20 -> 1132.8 | M20: =(G20/1000)*K20 -> 8533.76 | N20: =L20/E4 -> 19.2 | O20: =M20/F4 -> 15.774048
A21: 13 | B21: PROSOLVE 126 | C21: 122.8 | F21: 1.8 | G21: ='03-07-26'!G21+'04-07-26'!F21 -> 13.5 | H21: =F21/E4 -> 0.030508475 | I21: =(C21-F21)+D21 -> 121 | J21: =G21/F4 -> 0.024953789 | K21: 271400 | L21: =(F21/1000)*K21 -> 488.52 | M21: =(G21/1000)*K21 -> 3663.9 | N21: =L21/E4 -> 8.28 | O21: =M21/F4 -> 6.7724584
A22: 14 | B22: PROSOLVE ADV. | C22: 1770.6 | F22: 25.8 | G22: ='03-07-26'!G22+'04-07-26'!F22 -> 194.4 | H22: =F22/E4 -> 0.43728814 | I22: =(C22-F22)+D22 -> 1744.8 | J22: =G22/F4 -> 0.35933457 | K22: 271400 | L22: =(F22/1000)*K22 -> 7002.12 | M22: =(G22/1000)*K22 -> 52760.16 | N22: =L22/E4 -> 118.68 | O22: =M22/F4 -> 97.523401
A23: 15 | B23: BLEACHING POWDER (S) | C23: 100 | F23: 0 | G23: ='03-07-26'!G23+'04-07-26'!F23 -> 0 | H23: =F23/E4 -> 0 | I23: =(C23-F23)+D23 -> 100 | J23: =G23/F4 -> 0 | K23: 41000 | L23: =(F23/1000)*K23 -> 0 | M23: =(G23/1000)*K23 -> 0 | N23: =L23/E4 -> 0 | O23: =M23/F4 -> 0
A24: 16 | B24: SODIUM HYPO CHLORIDE [HYPO] | C24: 373.6 | F24: 6 | G24: ='03-07-26'!G24+'04-07-26'!F24 -> 24 | H24: =F24/E4 -> 0.10169492 | I24: =(C24-F24)+D24 -> 367.6 | J24: =G24/F4 -> 0.044362292 | K24: 24000 | L24: =(F24/1000)*K24 -> 144 | M24: =(G24/1000)*K24 -> 576 | N24: =L24/E4 -> 2.440678 | O24: =M24/F4 -> 1.064695
A25: 17 | B25: HCL [PULP MILL] | C25: 380 | F25: 0 | G25: ='03-07-26'!G25+'04-07-26'!F25 -> 0 | H25: =F25/E4 -> 0 | I25: =(C25-F25)+D25 -> 380 | J25: =G25/F4 -> 0 | K25: 13210 | L25: =(F25/1000)*K25 -> 0 | M25: =(G25/1000)*K25 -> 0 | N25: =L25/E4 -> 0 | O25: =M25/F4 -> 0
A26: 18 | B26: HCL [BOILER] | C26: 205 | F26: 5 | G26: ='03-07-26'!G26+'04-07-26'!F26 -> 35 | H26: =F26/E4 -> 0.084745763 | I26: =(C26-F26)+D26 -> 200 | J26: =G26/F4 -> 0.064695009 | K26: 14400 | L26: =(F26/1000)*K26 -> 72 | M26: =(G26/1000)*K26 -> 504 | N26: =L26/E4 -> 1.220339 | O26: =M26/F4 -> 0.93160813
A27: 19 | B27: pH BOOSTER [3230] (L) | C27: 190.5 | F27: 3.5 | G27: ='03-07-26'!G27+'04-07-26'!F27 -> 14.5 | H27: =F27/E4 -> 0.059322034 | I27: =(C27-F27)+D27 -> 187 | J27: =G27/F4 -> 0.026802218 | K27: 102000 | L27: =(F27/1000)*K27 -> 357 | M27: =(G27/1000)*K27 -> 1479 | N27: =L27/E4 -> 6.0508475 | O27: =M27/F4 -> 2.7338262
A28: 20 | B28: ANTI SCALEN [3220] (L) | C28: 160 | F28: 5 | G28: ='03-07-26'!G28+'04-07-26'!F28 -> 20 | H28: =F28/E4 -> 0.084745763 | I28: =(C28-F28)+D28 -> 155 | J28: =G28/F4 -> 0.036968577 | K28: 107000 | L28: =(F28/1000)*K28 -> 535 | M28: =(G28/1000)*K28 -> 2140 | N28: =L28/E4 -> 9.0677966 | O28: =M28/F4 -> 3.9556377
A29: 21 | B29: OXYGEN SCAVANGER [3210] (L) | C29: 157 | F29: 3 | G29: ='03-07-26'!G29+'04-07-26'!F29 -> 12 | H29: =F29/E4 -> 0.050847458 | I29: =(C29-F29)+D29 -> 154 | J29: =G29/F4 -> 0.022181146 | K29: 100000 | L29: =(F29/1000)*K29 -> 300 | M29: =(G29/1000)*K29 -> 1200 | N29: =L29/E4 -> 5.0847458 | O29: =M29/F4 -> 2.2181146
A30: 22 | B30: RO ANTI SCALEN [3291 (L) | C30: 60 | F30: 1 | G30: ='03-07-26'!G30+'04-07-26'!F30 -> 4 | H30: =F30/E4 -> 0.016949153 | I30: =(C30-F30)+D30 -> 59 | J30: =G30/F4 -> 0.0073937153 | K30: 255000 | L30: =(F30/1000)*K30 -> 255 | M30: =(G30/1000)*K30 -> 1020 | N30: =L30/E4 -> 4.3220339 | O30: =M30/F4 -> 1.8853974
A31: 23 | B31: CAUSTIC SODA FLAKES | C31: 480 | F31: 0 | G31: ='03-07-26'!G31+'04-07-26'!F31 -> 0 | H31: =F31/E4 -> 0 | I31: =(C31-F31)+D31 -> 480 | J31: =G31/F4 -> 0 | K31: 56000 | L31: =(F31/1000)*K31 -> 0 | M31: =(G31/1000)*K31 -> 0 | N31: =M30/F4 -> 1.8853974 | O31: =M31/F4 -> 0
A32: 24 | B32: DESCALING [3250] (L) | C32: 0 | F32: 0 | G32: ='03-07-26'!G32+'04-07-26'!F32 -> 0 | H32: =F32/E4 -> 0 | I32: =(C32-F32)+D32 -> 0 | J32: =G32/F4 -> 0 | K32: 90000 | L32: =(F32/1000)*K32 -> 0 | M32: =(G32/1000)*K32 -> 0 | N32: =M31/F4 -> 0 | O32: =M32/F4 -> 0
A33: S.NO. | B33: QUALITY WISE PRODUCTION | C33: NO. OF SET | D33: PM/C PRODUCTION (MT) | M33: TOTAL | N33: =SUM(N9:N32) -> 1198.1217 | O33: =SUM(O9:O32) -> 1164.7695
A34: 1 | B34: 180 GSM/22 BF (NATURAL) | C34: 0 | F34: =C34*E4/C41 -> 0 | N34: COSTING | O34: COSTING
A35: 2 | B35: 140 GSM/18 BF (NATURAL) | C35: 7 | F35: =C35*E4/C41 -> 11.472222 | N35: TODAY | O35: TO DATE
A36: 3 | B36: 120 GSM/20 BF (NATURAL) | C36: 19 | F36: =C36*E4/C41 -> 31.138889 | N36: Rs./Kg. | O36: Rs./Kg.
A37: 4 | B37: 120 GSM/18 BF (NATURAL) | C37: 10 | F37: =C37*E4/C41 -> 16.388889 | M37: TOTAL | N37: =N33/1000 -> 1.1981217 | O37: =O33/1000 -> 1.1647695
A38: 5
A39: 6
A40: 7
A41: 4 | B41: TOTAL | C41: =SUM(C34,C35,C36,C37,C38,C39,C40) -> 36 | D41: =SUM(F34,F35,F36,F37,F38,F39,F40) -> 59

Sheet 05-7-26
A1: SRI MK PAPER MILLS PVT. LTD.
A3: CHEMICAL CONSUMPTION / BALANCE & COSTING PER DAY & TODATE
A4: PRODUCTION ( MT ) | E4: 106 | F4: 647 | G4: 129.4 | H4: DATE : 05 - 07 - 2026
A5: PRODUCTION (MT) | C5: GOLDEN YELLOW | E5: 0 | F5: 0 | G5: 00.000(AVG)
A6: SR. | B6: CHEMICAL | C6: OPENING | D6: RECEIVED MATERIAL | F6: CONSUMED MATERIAL | H6: TODAY | I6: CHEMICAL | J6: TO DATE | K6: RATE | L6: TOTAL CONSUMED AMOUNT | N6: COSTING
A7: NO. | B7: NAME | C7: STOCK | D7: TO DAY | E7: TO DATE | F7: TO DAY | G7: TO DATE | H7: CONSUMPTION | I7: BALANCE | J7: CONSUMPTION | K7: RS.@ | L7: TODAY | M7: TO DATE | N7: TODAY | O7: TO DATE
C8: (Kgs.) | D8: (Kgs.) | E8: (Kgs.) | F8: (Kgs.) | G8: (Kgs.) | H8: (Kgs.)/MTP | I8: (Kgs.) | J8: (Kgs.)/MTP | K8: MT | L8: Rs. | M8: Rs. | N8: Rs./MTP | O8: Rs./MTP
A9: 1 | B9: STARCH | C9: 11350 | D9: 0 | E9: 13000 | F9: 2400 | G9: ='04-07-26'!G9+'05-7-26'!F9 -> 17450 | H9: =F9/E4 -> 22.641509 | I9: =(C9-F9)+D9 -> 8950 | J9: =G9/F4 -> 26.970634 | K9: 28500 | L9: =(F9/1000)*K9 -> 68400 | M9: =(G9/1000)*K9 -> 497325 | N9: =L9/E4 -> 645.28302 | O9: =M9/F4 -> 768.66306
A10: 2 | B10: PAC ( SOLID) | C10: 8240 | F10: 161 | G10: ='04-07-26'!G10+'05-7-26'!F10 -> 921 | H10: =F10/E4 -> 1.5188679 | I10: =(C10-F10)+D10 -> 8079 | J10: =G10/F4 -> 1.423493 | K10: 35500 | L10: =(F10/1000)*K10 -> 5715.5 | M10: =(G10/1000)*K10 -> 32695.5 | N10: =L10/E4 -> 53.919811 | O10: =M10/F4 -> 50.534003
A11: 3 | B11: SURFACE SIZE (700C) | C11: 6591 | F11: 46 | G11: ='04-07-26'!G11+'05-7-26'!F11 -> 275 | H11: =F11/E4 -> 0.43396226 | I11: =(C11-F11)+D11 -> 6545 | J11: =G11/F4 -> 0.42503864 | K11: 98000 | L11: =(F11/1000)*K11 -> 4508 | M11: =(G11/1000)*K11 -> 26950 | N11: =L11/E4 -> 42.528302 | O11: =M11/F4 -> 41.653787
A12: 4 | B12: ENZYME (L) | C12: 20.68 | F12: 0.08 | G12: ='04-07-26'!G12+'05-7-26'!F12 -> 0.4 | H12: =F12/E4 -> 0.00075471698 | I12: =(C12-F12)+D12 -> 20.6 | J12: =G12/F4 -> 0.00061823802 | K12: 750000 | L12: =(F12/1000)*K12 -> 60 | M12: =(G12/1000)*K12 -> 300 | N12: =L12/E4 -> 0.56603774 | O12: =M12/F4 -> 0.46367852
A13: 5 | B13: RETENTION AID (2024) | C13: 425 | F13: 18 | G13: ='04-07-26'!G13+'05-7-26'!F13 -> 93 | H13: =F13/E4 -> 0.16981132 | I13: =(C13-F13)+D13 -> 407 | J13: =G13/F4 -> 0.14374034 | K13: 350000 | L13: =(F13/1000)*K13 -> 6300 | M13: =(G13/1000)*K13 -> 32550 | N13: =L13/E4 -> 59.433962 | O13: =M13/F4 -> 50.309119
A14: 6 | B14: DEFOAMER (SE 100) | C14: 2195 | F14: 35 | G14: ='04-07-26'!G14+'05-7-26'!F14 -> 240 | H14: =F14/E4 -> 0.33018868 | I14: =(C14-F14)+D14 -> 2160 | J14: =G14/F4 -> 0.37094281 | K14: 204500 | L14: =(F14/1000)*K14 -> 7157.5 | M14: =(G14/1000)*K14 -> 49080 | N14: =L14/E4 -> 67.523585 | O14: =M14/F4 -> 75.857805
A15: 7 | B15: COAGULANT (CL 200) | C15: 1563 | F15: 34 | G15: ='04-07-26'!G15+'05-7-26'!F15 -> 221 | H15: =F15/E4 -> 0.32075472 | I15: =(C15-F15)+D15 -> 1529 | J15: =G15/F4 -> 0.34157651 | K15: 129500 | L15: =(F15/1000)*K15 -> 4403 | M15: =(G15/1000)*K15 -> 28619.5 | N15: =L15/E4 -> 41.537736 | O15: =M15/F4 -> 44.234158
A16: 8 | B16: KROFTA (303) | C16: 920 | F16: 15 | G16: ='04-07-26'!G16+'05-7-26'!F16 -> 80 | H16: =F16/E4 -> 0.14150943 | I16: =(C16-F16)+D16 -> 905 | J16: =G16/F4 -> 0.1236476 | K16: 219500 | L16: =(F16/1000)*K16 -> 3292.5 | M16: =(G16/1000)*K16 -> 17560 | N16: =L16/E4 -> 31.061321 | O16: =M16/F4 -> 27.140649
A17: 9 | B17: BELT PRESS (SUCHEM - 638 ) | C17: 21 | F17: 0 | G17: ='04-07-26'!G17+'05-7-26'!F17 -> 0 | H17: =F17/E4 -> 0 | I17: =(C17-F17)+D17 -> 21 | J17: =G17/F4 -> 0 | K17: 348200 | L17: =(F17/1000)*K17 -> 0 | M17: =(G17/1000)*K17 -> 0 | N17: =L17/E4 -> 0 | O17: =M17/F4 -> 0
A18: 10 | B18: GOLDEN YELLOW DYE | C18: 3950 | F18: 0 | G18: ='04-07-26'!G18+'05-7-26'!F18 -> 0 | H18: =F18/E4 -> 0 | I18: =(C18-F18)+D18 -> 3950 | J18: =G18/F4 -> 0 | K18: 172000 | L18: =(F18/1000)*K18 -> 0 | M18: =(G18/1000)*K18 -> 0 | N18: =L18/E4 -> 0 | O18: =M18/F4 -> 0
A19: 11 | B19: SE-BOND 102 (CRACKING AGENT) | C19: 48 | F19: 0 | G19: ='04-07-26'!G19+'05-7-26'!F19 -> 0 | H19: =F19/E4 -> 0 | I19: =(C19-F19)+D19 -> 48 | J19: =G19/F4 -> 0 | K19: 200000 | L19: =(F19/1000)*K19 -> 0 | M19: =(G19/1000)*K19 -> 0 | N19: =L19/E4 -> 0 | O19: =M19/F4 -> 0
A20: 12 | B20: PROMASK 192 | C20: 140.6 | F20: 5.1 | G20: ='04-07-26'!G20+'05-7-26'!F20 -> 27.7 | H20: =F20/E4 -> 0.048113208 | I20: =(C20-F20)+D20 -> 135.5 | J20: =G20/F4 -> 0.042812983 | K20: 377600 | L20: =(F20/1000)*K20 -> 1925.76 | M20: =(G20/1000)*K20 -> 10459.52 | N20: =L20/E4 -> 18.167547 | O20: =M20/F4 -> 16.166182
A21: 13 | B21: PROSOLVE 126 | C21: 121 | F21: 3 | G21: ='04-07-26'!G21+'05-7-26'!F21 -> 16.5 | H21: =F21/E4 -> 0.028301887 | I21: =(C21-F21)+D21 -> 118 | J21: =G21/F4 -> 0.025502318 | K21: 271400 | L21: =(F21/1000)*K21 -> 814.2 | M21: =(G21/1000)*K21 -> 4478.1 | N21: =L21/E4 -> 7.6811321 | O21: =M21/F4 -> 6.9213292
A22: 14 | B22: PROSOLVE ADV. | C22: 1744.8 | F22: 43.8 | G22: ='04-07-26'!G22+'05-7-26'!F22 -> 238.2 | H22: =F22/E4 -> 0.41320755 | I22: =(C22-F22)+D22 -> 1701 | J22: =G22/F4 -> 0.36816074 | K22: 271400 | L22: =(F22/1000)*K22 -> 11887.32 | M22: =(G22/1000)*K22 -> 64647.48 | N22: =L22/E4 -> 112.14453 | O22: =M22/F4 -> 99.918825
A23: 15 | B23: BLEACHING POWDER (S) | C23: 100 | F23: 0 | G23: ='04-07-26'!G23+'05-7-26'!F23 -> 0 | H23: =F23/E4 -> 0 | I23: =(C23-F23)+D23 -> 100 | J23: =G23/F4 -> 0 | K23: 41000 | L23: =(F23/1000)*K23 -> 0 | M23: =(G23/1000)*K23 -> 0 | N23: =L23/E4 -> 0 | O23: =M23/F4 -> 0
A24: 16 | B24: SODIUM HYPO CHLORIDE [HYPO] | C24: 367.6 | F24: 6 | G24: ='04-07-26'!G24+'05-7-26'!F24 -> 30 | H24: =F24/E4 -> 0.056603774 | I24: =(C24-F24)+D24 -> 361.6 | J24: =G24/F4 -> 0.046367852 | K24: 24000 | L24: =(F24/1000)*K24 -> 144 | M24: =(G24/1000)*K24 -> 720 | N24: =L24/E4 -> 1.3584906 | O24: =M24/F4 -> 1.1128284
A25: 17 | B25: HCL [PULP MILL] | C25: 380 | F25: 0 | G25: ='04-07-26'!G25+'05-7-26'!F25 -> 0 | H25: =F25/E4 -> 0 | I25: =(C25-F25)+D25 -> 380 | J25: =G25/F4 -> 0 | K25: 13210 | L25: =(F25/1000)*K25 -> 0 | M25: =(G25/1000)*K25 -> 0 | N25: =L25/E4 -> 0 | O25: =M25/F4 -> 0
A26: 18 | B26: HCL [BOILER] | C26: 210 | F26: 5 | G26: ='04-07-26'!G26+'05-7-26'!F26 -> 40 | H26: =F26/E4 -> 0.047169811 | I26: =(C26-F26)+D26 -> 205 | J26: =G26/F4 -> 0.061823802 | K26: 14400 | L26: =(F26/1000)*K26 -> 72 | M26: =(G26/1000)*K26 -> 576 | N26: =L26/E4 -> 0.67924528 | O26: =M26/F4 -> 0.89026275
A27: 19 | B27: pH BOOSTER [3230] (L) | C27: 190.5 | F27: 3.5 | G27: ='04-07-26'!G27+'05-7-26'!F27 -> 18 | H27: =F27/E4 -> 0.033018868 | I27: =(C27-F27)+D27 -> 187 | J27: =G27/F4 -> 0.027820711 | K27: 102000 | L27: =(F27/1000)*K27 -> 357 | M27: =(G27/1000)*K27 -> 1836 | N27: =L27/E4 -> 3.3679245 | O27: =M27/F4 -> 2.8377125
A28: 20 | B28: ANTI SCALEN [3220] (L) | C28: 160 | F28: 5 | G28: ='04-07-26'!G28+'05-7-26'!F28 -> 25 | H28: =F28/E4 -> 0.047169811 | I28: =(C28-F28)+D28 -> 155 | J28: =G28/F4 -> 0.038639876 | K28: 107000 | L28: =(F28/1000)*K28 -> 535 | M28: =(G28/1000)*K28 -> 2675 | N28: =L28/E4 -> 5.0471698 | O28: =M28/F4 -> 4.1344668
A29: 21 | B29: OXYGEN SCAVANGER [3210] (L) | C29: 157 | F29: 3 | G29: ='04-07-26'!G29+'05-7-26'!F29 -> 15 | H29: =F29/E4 -> 0.028301887 | I29: =(C29-F29)+D29 -> 154 | J29: =G29/F4 -> 0.023183926 | K29: 100000 | L29: =(F29/1000)*K29 -> 300 | M29: =(G29/1000)*K29 -> 1500 | N29: =L29/E4 -> 2.8301887 | O29: =M29/F4 -> 2.3183926
A30: 22 | B30: RO ANTI SCALEN [3291 (L) | C30: 60 | F30: 1 | G30: ='04-07-26'!G30+'05-7-26'!F30 -> 5 | H30: =F30/E4 -> 0.0094339623 | I30: =(C30-F30)+D30 -> 59 | J30: =G30/F4 -> 0.0077279753 | K30: 255000 | L30: =(F30/1000)*K30 -> 255 | M30: =(G30/1000)*K30 -> 1275 | N30: =L30/E4 -> 2.4056604 | O30: =M30/F4 -> 1.9706337
A31: 23 | B31: CAUSTIC SODA FLAKES | C31: 480 | F31: 0 | G31: ='04-07-26'!G31+'05-7-26'!F31 -> 0 | H31: =F31/E4 -> 0 | I31: =(C31-F31)+D31 -> 480 | J31: =G31/F4 -> 0 | K31: 56000 | L31: =(F31/1000)*K31 -> 0 | M31: =(G31/1000)*K31 -> 0 | N31: =M30/F4 -> 1.9706337 | O31: =M31/F4 -> 0
A32: 24 | B32: DESCALING [3250] (L) | C32: 0 | F32: 0 | G32: ='04-07-26'!G32+'05-7-26'!F32 -> 0 | H32: =F32/E4 -> 0 | I32: =(C32-F32)+D32 -> 0 | J32: =G32/F4 -> 0 | K32: 90000 | L32: =(F32/1000)*K32 -> 0 | M32: =(G32/1000)*K32 -> 0 | N32: =M31/F4 -> 0 | O32: =M32/F4 -> 0
A33: S.NO. | B33: QUALITY WISE PRODUCTION | C33: NO. OF SET | D33: PM/C PRODUCTION (MT) | M33: TOTAL | N33: =SUM(N9:N32) -> 1097.5063 | O33: =SUM(O9:O32) -> 1195.1269
A34: 1 | F34: =C34*E4/C41 -> 0 | N34: COSTING | O34: COSTING
A35: 2 | F35: =C35*E4/C41 -> 0 | N35: TODAY | O35: TO DATE
A36: 3 | B36: 140 GSM/18 BF (NATURAL) | C36: 13 | F36: =C36*E4/C41 -> 21.2 | N36: Rs./Kg. | O36: Rs./Kg.
A37: 4 | B37: 120 GSM/18 BF (NATURAL) | C37: 52 | F37: =C37*E4/C41 -> 84.8 | M37: TOTAL | N37: =N33/1000 -> 1.0975063 | O37: =O33/1000 -> 1.1951269
A38: 5
A39: 6
A40: 7
A41: 4 | B41: TOTAL | C41: =SUM(C34,C35,C36,C37,C38,C39,C40) -> 65 | D41: =SUM(F34,F35,F36,F37,F38,F39,F40) -> 106

Sheet 06-07-26
A1: SRI MK PAPER MILLS PVT. LTD.
A3: CHEMICAL CONSUMPTION / BALANCE & COSTING PER DAY & TODATE
A4: PRODUCTION ( MT ) | E4: 152 | F4: 799 | G4: 133.166 | H4: DATE : 06 - 07 - 2026
A5: PRODUCTION (MT) | C5: GOLDEN YELLOW | E5: 0 | F5: 0 | G5: 00.000(AVG)
A6: SR. | B6: CHEMICAL | C6: OPENING | D6: RECEIVED MATERIAL | F6: CONSUMED MATERIAL | H6: TODAY | I6: CHEMICAL | J6: TO DATE | K6: RATE | L6: TOTAL CONSUMED AMOUNT | N6: COSTING
A7: NO. | B7: NAME | C7: STOCK | D7: TO DAY | E7: TO DATE | F7: TO DAY | G7: TO DATE | H7: CONSUMPTION | I7: BALANCE | J7: CONSUMPTION | K7: RS.@ | L7: TODAY | M7: TO DATE | N7: TODAY | O7: TO DATE
C8: (Kgs.) | D8: (Kgs.) | E8: (Kgs.) | F8: (Kgs.) | G8: (Kgs.) | H8: (Kgs.)/MTP | I8: (Kgs.) | J8: (Kgs.)/MTP | K8: MT | L8: Rs. | M8: Rs. | N8: Rs./MTP | O8: Rs./MTP
A9: 1 | B9: STARCH | C9: 8950 | D9: 15000 | E9: 28000 | F9: 3400 | G9: ='05-7-26'!G9+'06-07-26'!F9 -> 20850 | H9: =F9/E4 -> 22.368421 | I9: =(C9-F9)+D9 -> 20550 | J9: =G9/F4 -> 26.095119 | K9: 28500 | L9: =(F9/1000)*K9 -> 96900 | M9: =(G9/1000)*K9 -> 594225 | N9: =L9/E4 -> 637.5 | O9: =M9/F4 -> 743.71089
A10: 2 | B10: PAC ( SOLID) | C10: 8079 | F10: 249 | G10: ='05-7-26'!G10+'06-07-26'!F10 -> 1170 | H10: =F10/E4 -> 1.6381579 | I10: =(C10-F10)+D10 -> 7830 | J10: =G10/F4 -> 1.4643304 | K10: 35500 | L10: =(F10/1000)*K10 -> 8839.5 | M10: =(G10/1000)*K10 -> 41535 | N10: =L10/E4 -> 58.154605 | O10: =M10/F4 -> 51.98373
A11: 3 | B11: SURFACE SIZE (700C) | C11: 6545 | F11: 72 | G11: ='05-7-26'!G11+'06-07-26'!F11 -> 347 | H11: =F11/E4 -> 0.47368421 | I11: =(C11-F11)+D11 -> 6473 | J11: =G11/F4 -> 0.43429287 | K11: 98000 | L11: =(F11/1000)*K11 -> 7056 | M11: =(G11/1000)*K11 -> 34006 | N11: =L11/E4 -> 46.421053 | O11: =M11/F4 -> 42.560701
A12: 4 | B12: ENZYME (L) | C12: 20.6 | F12: 0.08 | G12: ='05-7-26'!G12+'06-07-26'!F12 -> 0.48 | H12: =F12/E4 -> 0.00052631579 | I12: =(C12-F12)+D12 -> 20.52 | J12: =G12/F4 -> 0.00060075094 | K12: 750000 | L12: =(F12/1000)*K12 -> 60 | M12: =(G12/1000)*K12 -> 360 | N12: =L12/E4 -> 0.39473684 | O12: =M12/F4 -> 0.4505632
A13: 5 | B13: RETENTION AID (2024) | C13: 407 | F13: 23 | G13: ='05-7-26'!G13+'06-07-26'!F13 -> 116 | H13: =F13/E4 -> 0.15131579 | I13: =(C13-F13)+D13 -> 384 | J13: =G13/F4 -> 0.14518148 | K13: 350000 | L13: =(F13/1000)*K13 -> 8050 | M13: =(G13/1000)*K13 -> 40600 | N13: =L13/E4 -> 52.960526 | O13: =M13/F4 -> 50.813517
A14: 6 | B14: DEFOAMER (SE 100) | C14: 2160 | F14: 50 | G14: ='05-7-26'!G14+'06-07-26'!F14 -> 290 | H14: =F14/E4 -> 0.32894737 | I14: =(C14-F14)+D14 -> 2110 | J14: =G14/F4 -> 0.36295369 | K14: 204500 | L14: =(F14/1000)*K14 -> 10225 | M14: =(G14/1000)*K14 -> 59305 | N14: =L14/E4 -> 67.269737 | O14: =M14/F4 -> 74.22403
A15: 7 | B15: COAGULANT (CL 200) | C15: 1529 | F15: 54 | G15: ='05-7-26'!G15+'06-07-26'!F15 -> 275 | H15: =F15/E4 -> 0.35526316 | I15: =(C15-F15)+D15 -> 1475 | J15: =G15/F4 -> 0.34418023 | K15: 129500 | L15: =(F15/1000)*K15 -> 6993 | M15: =(G15/1000)*K15 -> 35612.5 | N15: =L15/E4 -> 46.006579 | O15: =M15/F4 -> 44.571339
A16: 8 | B16: KROFTA (303) | C16: 905 | F16: 20 | G16: ='05-7-26'!G16+'06-07-26'!F16 -> 100 | H16: =F16/E4 -> 0.13157895 | I16: =(C16-F16)+D16 -> 885 | J16: =G16/F4 -> 0.12515645 | K16: 219500 | L16: =(F16/1000)*K16 -> 4390 | M16: =(G16/1000)*K16 -> 21950 | N16: =L16/E4 -> 28.881579 | O16: =M16/F4 -> 27.47184
A17: 9 | B17: BELT PRESS (SUCHEM - 638 ) | C17: 21 | F17: 0 | G17: ='05-7-26'!G17+'06-07-26'!F17 -> 0 | H17: =F17/E4 -> 0 | I17: =(C17-F17)+D17 -> 21 | J17: =G17/F4 -> 0 | K17: 348200 | L17: =(F17/1000)*K17 -> 0 | M17: =(G17/1000)*K17 -> 0 | N17: =L17/E4 -> 0 | O17: =M17/F4 -> 0
A18: 10 | B18: GOLDEN YELLOW DYE | C18: 3950 | F18: 0 | G18: ='05-7-26'!G18+'06-07-26'!F18 -> 0 | H18: =F18/E4 -> 0 | I18: =(C18-F18)+D18 -> 3950 | J18: =G18/F4 -> 0 | K18: 172000 | L18: =(F18/1000)*K18 -> 0 | M18: =(G18/1000)*K18 -> 0 | N18: =L18/E4 -> 0 | O18: =M18/F4 -> 0
A19: 11 | B19: SE-BOND 102 (CRACKING AGENT) | C19: 48 | F19: 0 | G19: ='05-7-26'!G19+'06-07-26'!F19 -> 0 | H19: =F19/E4 -> 0 | I19: =(C19-F19)+D19 -> 48 | J19: =G19/F4 -> 0 | K19: 200000 | L19: =(F19/1000)*K19 -> 0 | M19: =(G19/1000)*K19 -> 0 | N19: =L19/E4 -> 0 | O19: =M19/F4 -> 0
A20: 12 | B20: PROMASK 192 | C20: 135.5 | F20: 7.2 | G20: ='05-7-26'!G20+'06-07-26'!F20 -> 34.9 | H20: =F20/E4 -> 0.047368421 | I20: =(C20-F20)+D20 -> 128.3 | J20: =G20/F4 -> 0.043679599 | K20: 377600 | L20: =(F20/1000)*K20 -> 2718.72 | M20: =(G20/1000)*K20 -> 13178.24 | N20: =L20/E4 -> 17.886316 | O20: =M20/F4 -> 16.493417
A21: 13 | B21: PROSOLVE 126 | C21: 118 | F21: 4.3 | G21: ='05-7-26'!G21+'06-07-26'!F21 -> 20.8 | H21: =F21/E4 -> 0.028289474 | I21: =(C21-F21)+D21 -> 113.7 | J21: =G21/F4 -> 0.026032541 | K21: 271400 | L21: =(F21/1000)*K21 -> 1167.02 | M21: =(G21/1000)*K21 -> 5645.12 | N21: =L21/E4 -> 7.6777632 | O21: =M21/F4 -> 7.0652315
A22: 14 | B22: PROSOLVE ADV. | C22: 1701 | F22: 61.9 | G22: ='05-7-26'!G22+'06-07-26'!F22 -> 300.1 | H22: =F22/E4 -> 0.40723684 | I22: =(C22-F22)+D22 -> 1639.1 | J22: =G22/F4 -> 0.37559449 | K22: 271400 | L22: =(F22/1000)*K22 -> 16799.66 | M22: =(G22/1000)*K22 -> 81447.14 | N22: =L22/E4 -> 110.52408 | O22: =M22/F4 -> 101.93635
A23: 15 | B23: BLEACHING POWDER (S) | C23: 100 | F23: 0 | G23: ='05-7-26'!G23+'06-07-26'!F23 -> 0 | H23: =F23/E4 -> 0 | I23: =(C23-F23)+D23 -> 100 | J23: =G23/F4 -> 0 | K23: 41000 | L23: =(F23/1000)*K23 -> 0 | M23: =(G23/1000)*K23 -> 0 | N23: =L23/E4 -> 0 | O23: =M23/F4 -> 0
A24: 16 | B24: SODIUM HYPO CHLORIDE [HYPO] | C24: 361.6 | F24: 6 | G24: ='05-7-26'!G24+'06-07-26'!F24 -> 36 | H24: =F24/E4 -> 0.039473684 | I24: =(C24-F24)+D24 -> 355.6 | J24: =G24/F4 -> 0.04505632 | K24: 24000 | L24: =(F24/1000)*K24 -> 144 | M24: =(G24/1000)*K24 -> 864 | N24: =L24/E4 -> 0.94736842 | O24: =M24/F4 -> 1.0813517
A25: 17 | B25: HCL [PULP MILL] | C25: 380 | F25: 0 | G25: ='05-7-26'!G25+'06-07-26'!F25 -> 0 | H25: =F25/E4 -> 0 | I25: =(C25-F25)+D25 -> 380 | J25: =G25/F4 -> 0 | K25: 13210 | L25: =(F25/1000)*K25 -> 0 | M25: =(G25/1000)*K25 -> 0 | N25: =L25/E4 -> 0 | O25: =M25/F4 -> 0
A26: 18 | B26: HCL [BOILER] | C26: 205 | F26: 5 | G26: ='05-7-26'!G26+'06-07-26'!F26 -> 45 | H26: =F26/E4 -> 0.032894737 | I26: =(C26-F26)+D26 -> 200 | J26: =G26/F4 -> 0.056320401 | K26: 14400 | L26: =(F26/1000)*K26 -> 72 | M26: =(G26/1000)*K26 -> 648 | N26: =L26/E4 -> 0.47368421 | O26: =M26/F4 -> 0.81101377
A27: 19 | B27: pH BOOSTER [3230] (L) | C27: 187 | F27: 3.5 | G27: ='05-7-26'!G27+'06-07-26'!F27 -> 21.5 | H27: =F27/E4 -> 0.023026316 | I27: =(C27-F27)+D27 -> 183.5 | J27: =G27/F4 -> 0.026908636 | K27: 102000 | L27: =(F27/1000)*K27 -> 357 | M27: =(G27/1000)*K27 -> 2193 | N27: =L27/E4 -> 2.3486842 | O27: =M27/F4 -> 2.7446809
A28: 20 | B28: ANTI SCALEN [3220] (L) | C28: 155 | F28: 5 | G28: ='05-7-26'!G28+'06-07-26'!F28 -> 30 | H28: =F28/E4 -> 0.032894737 | I28: =(C28-F28)+D28 -> 150 | J28: =G28/F4 -> 0.037546934 | K28: 107000 | L28: =(F28/1000)*K28 -> 535 | M28: =(G28/1000)*K28 -> 3210 | N28: =L28/E4 -> 3.5197368 | O28: =M28/F4 -> 4.0175219
A29: 21 | B29: OXYGEN SCAVANGER [3210] (L) | C29: 154 | F29: 3 | G29: ='05-7-26'!G29+'06-07-26'!F29 -> 18 | H29: =F29/E4 -> 0.019736842 | I29: =(C29-F29)+D29 -> 151 | J29: =G29/F4 -> 0.02252816 | K29: 100000 | L29: =(F29/1000)*K29 -> 300 | M29: =(G29/1000)*K29 -> 1800 | N29: =L29/E4 -> 1.9736842 | O29: =M29/F4 -> 2.252816
A30: 22 | B30: RO ANTI SCALEN [3291 (L) | C30: 59 | F30: 1 | G30: ='05-7-26'!G30+'06-07-26'!F30 -> 6 | H30: =F30/E4 -> 0.0065789474 | I30: =(C30-F30)+D30 -> 58 | J30: =G30/F4 -> 0.0075093867 | K30: 255000 | L30: =(F30/1000)*K30 -> 255 | M30: =(G30/1000)*K30 -> 1530 | N30: =L30/E4 -> 1.6776316 | O30: =M30/F4 -> 1.9148936
A31: 23 | B31: CAUSTIC SODA FLAKES | C31: 480 | F31: 0 | G31: ='05-7-26'!G31+'06-07-26'!F31 -> 0 | H31: =F31/E4 -> 0 | I31: =(C31-F31)+D31 -> 480 | J31: =G31/F4 -> 0 | K31: 56000 | L31: =(F31/1000)*K31 -> 0 | M31: =(G31/1000)*K31 -> 0 | N31: =M30/F4 -> 1.9148936 | O31: =M31/F4 -> 0
A32: 24 | B32: DESCALING [3250] (L) | C32: 0 | F32: 0 | G32: ='05-7-26'!G32+'06-07-26'!F32 -> 0 | H32: =F32/E4 -> 0 | I32: =(C32-F32)+D32 -> 0 | J32: =G32/F4 -> 0 | K32: 90000 | L32: =(F32/1000)*K32 -> 0 | M32: =(G32/1000)*K32 -> 0 | N32: =M31/F4 -> 0 | O32: =M32/F4 -> 0
A33: S.NO. | B33: QUALITY WISE PRODUCTION | C33: NO. OF SET | D33: PM/C PRODUCTION (MT) | M33: TOTAL | N33: =SUM(N9:N32) -> 1086.5327 | O33: =SUM(O9:O32) -> 1174.1039
A34: 1 | F34: =C34*E4/C41 -> 0 | N34: COSTING | O34: COSTING
A35: 2 | F35: =C35*E4/C41 -> 0 | N35: TODAY | O35: TO DATE
A36: 3 | C36: 0 | F36: =C36*E4/C41 -> 0 | N36: Rs./Kg. | O36: Rs./Kg.
A37: 4 | B37: 120 GSM/18 BF (NATURAL) | C37: 91 | F37: =C37*E4/C41 -> 152 | M37: TOTAL | N37: =N33/1000 -> 1.0865327 | O37: =O33/1000 -> 1.1741039
A38: 5
A39: 6
A40: 7
A41: 4 | B41: TOTAL | C41: =SUM(C34,C35,C36,C37,C38,C39,C40) -> 91 | D41: =SUM(F34,F35,F36,F37,F38,F39,F40) -> 152

Sheet 07-07-26
A1: SRI MK PAPER MILLS PVT. LTD.
A3: CHEMICAL CONSUMPTION / BALANCE & COSTING PER DAY & TODATE
A4: PRODUCTION ( MT ) | E4: 52 | F4: 851 | G4: 121.571 | H4: DATE : 07 - 07 - 2026
A5: PRODUCTION (MT) | C5: GOLDEN YELLOW | E5: 0 | F5: 0 | G5: 00.000(AVG)
A6: SR. | B6: CHEMICAL | C6: OPENING | D6: RECEIVED MATERIAL | F6: CONSUMED MATERIAL | H6: TODAY | I6: CHEMICAL | J6: TO DATE | K6: RATE | L6: TOTAL CONSUMED AMOUNT | N6: COSTING
A7: NO. | B7: NAME | C7: STOCK | D7: TO DAY | E7: TO DATE | F7: TO DAY | G7: TO DATE | H7: CONSUMPTION | I7: BALANCE | J7: CONSUMPTION | K7: RS.@ | L7: TODAY | M7: TO DATE | N7: TODAY | O7: TO DATE
C8: (Kgs.) | D8: (Kgs.) | E8: (Kgs.) | F8: (Kgs.) | G8: (Kgs.) | H8: (Kgs.)/MTP | I8: (Kgs.) | J8: (Kgs.)/MTP | K8: MT | L8: Rs. | M8: Rs. | N8: Rs./MTP | O8: Rs./MTP
A9: 1 | B9: STARCH | C9: 20550 | D9: 0 | E9: 28000 | F9: 1150 | G9: ='06-07-26'!G9+'07-07-26'!F9 -> 22000 | H9: =F9/E4 -> 22.115385 | I9: =(C9-F9)+D9 -> 19400 | J9: =G9/F4 -> 25.851939 | K9: 28500 | L9: =(F9/1000)*K9 -> 32775 | M9: =(G9/1000)*K9 -> 627000 | N9: =L9/E4 -> 630.28846 | O9: =M9/F4 -> 736.78026
A10: 2 | B10: PAC ( SOLID) | C10: 7830 | F10: 85 | G10: ='06-07-26'!G10+'07-07-26'!F10 -> 1255 | H10: =F10/E4 -> 1.6346154 | I10: =(C10-F10)+D10 -> 7745 | J10: =G10/F4 -> 1.4747356 | K10: 35500 | L10: =(F10/1000)*K10 -> 3017.5 | M10: =(G10/1000)*K10 -> 44552.5 | N10: =L10/E4 -> 58.028846 | O10: =M10/F4 -> 52.353114
A11: 3 | B11: SURFACE SIZE (700C) | C11: 6473 | F11: 24 | G11: ='06-07-26'!G11+'07-07-26'!F11 -> 371 | H11: =F11/E4 -> 0.46153846 | I11: =(C11-F11)+D11 -> 6449 | J11: =G11/F4 -> 0.4359577 | K11: 98000 | L11: =(F11/1000)*K11 -> 2352 | M11: =(G11/1000)*K11 -> 36358 | N11: =L11/E4 -> 45.230769 | O11: =M11/F4 -> 42.723854
A12: 4 | B12: ENZYME (L) | C12: 20.52 | F12: 0.08 | G12: ='06-07-26'!G12+'07-07-26'!F12 -> 0.56 | H12: =F12/E4 -> 0.0015384615 | I12: =(C12-F12)+D12 -> 20.44 | J12: =G12/F4 -> 0.00065804935 | K12: 750000 | L12: =(F12/1000)*K12 -> 60 | M12: =(G12/1000)*K12 -> 420 | N12: =L12/E4 -> 1.1538462 | O12: =M12/F4 -> 0.49353702
A13: 5 | B13: RETENTION AID (2024) | C13: 384 | F13: 11 | G13: ='06-07-26'!G13+'07-07-26'!F13 -> 127 | H13: =F13/E4 -> 0.21153846 | I13: =(C13-F13)+D13 -> 373 | J13: =G13/F4 -> 0.14923619 | K13: 350000 | L13: =(F13/1000)*K13 -> 3850 | M13: =(G13/1000)*K13 -> 44450 | N13: =L13/E4 -> 74.038462 | O13: =M13/F4 -> 52.232667
A14: 6 | B14: DEFOAMER (SE 100) | C14: 2110 | F14: 20 | G14: ='06-07-26'!G14+'07-07-26'!F14 -> 310 | H14: =F14/E4 -> 0.38461538 | I14: =(C14-F14)+D14 -> 2090 | J14: =G14/F4 -> 0.36427732 | K14: 204500 | L14: =(F14/1000)*K14 -> 4090 | M14: =(G14/1000)*K14 -> 63395 | N14: =L14/E4 -> 78.653846 | O14: =M14/F4 -> 74.494712
A15: 7 | B15: COAGULANT (CL 200) | C15: 1475 | F15: 20 | G15: ='06-07-26'!G15+'07-07-26'!F15 -> 295 | H15: =F15/E4 -> 0.38461538 | I15: =(C15-F15)+D15 -> 1455 | J15: =G15/F4 -> 0.346651 | K15: 129500 | L15: =(F15/1000)*K15 -> 2590 | M15: =(G15/1000)*K15 -> 38202.5 | N15: =L15/E4 -> 49.807692 | O15: =M15/F4 -> 44.891304
A16: 8 | B16: KROFTA (303) | C16: 885 | F16: 10 | G16: ='06-07-26'!G16+'07-07-26'!F16 -> 110 | H16: =F16/E4 -> 0.19230769 | I16: =(C16-F16)+D16 -> 875 | J16: =G16/F4 -> 0.12925969 | K16: 219500 | L16: =(F16/1000)*K16 -> 2195 | M16: =(G16/1000)*K16 -> 24145 | N16: =L16/E4 -> 42.211538 | O16: =M16/F4 -> 28.372503
A17: 9 | B17: BELT PRESS (SUCHEM - 638 ) | C17: 21 | F17: 0 | G17: ='06-07-26'!G17+'07-07-26'!F17 -> 0 | H17: =F17/E4 -> 0 | I17: =(C17-F17)+D17 -> 21 | J17: =G17/F4 -> 0 | K17: 348200 | L17: =(F17/1000)*K17 -> 0 | M17: =(G17/1000)*K17 -> 0 | N17: =L17/E4 -> 0 | O17: =M17/F4 -> 0
A18: 10 | B18: GOLDEN YELLOW DYE | C18: 3950 | F18: 0 | G18: ='06-07-26'!G18+'07-07-26'!F18 -> 0 | H18: =F18/E4 -> 0 | I18: =(C18-F18)+D18 -> 3950 | J18: =G18/F4 -> 0 | K18: 172000 | L18: =(F18/1000)*K18 -> 0 | M18: =(G18/1000)*K18 -> 0 | N18: =L18/E4 -> 0 | O18: =M18/F4 -> 0
A19: 11 | B19: SE-BOND 102 (CRACKING AGENT) | C19: 48 | F19: 0 | G19: ='06-07-26'!G19+'07-07-26'!F19 -> 0 | H19: =F19/E4 -> 0 | I19: =(C19-F19)+D19 -> 48 | J19: =G19/F4 -> 0 | K19: 200000 | L19: =(F19/1000)*K19 -> 0 | M19: =(G19/1000)*K19 -> 0 | N19: =L19/E4 -> 0 | O19: =M19/F4 -> 0
A20: 12 | B20: PROMASK 192 | C20: 128.3 | F20: 2.4 | G20: ='06-07-26'!G20+'07-07-26'!F20 -> 37.3 | H20: =F20/E4 -> 0.046153846 | I20: =(C20-F20)+D20 -> 125.9 | J20: =G20/F4 -> 0.043830787 | K20: 377600 | L20: =(F20/1000)*K20 -> 906.24 | M20: =(G20/1000)*K20 -> 14084.48 | N20: =L20/E4 -> 17.427692 | O20: =M20/F4 -> 16.550505
A21: 13 | B21: PROSOLVE 126 | C21: 113.7 | F21: 1.4 | G21: ='06-07-26'!G21+'07-07-26'!F21 -> 22.2 | H21: =F21/E4 -> 0.026923077 | I21: =(C21-F21)+D21 -> 112.3 | J21: =G21/F4 -> 0.026086957 | K21: 271400 | L21: =(F21/1000)*K21 -> 379.96 | M21: =(G21/1000)*K21 -> 6025.08 | N21: =L21/E4 -> 7.3069231 | O21: =M21/F4 -> 7.08
A22: 14 | B22: PROSOLVE ADV. | C22: 1639.1 | F22: 20.6 | G22: ='06-07-26'!G22+'07-07-26'!F22 -> 320.7 | H22: =F22/E4 -> 0.39615385 | I22: =(C22-F22)+D22 -> 1618.5 | J22: =G22/F4 -> 0.37685076 | K22: 271400 | L22: =(F22/1000)*K22 -> 5590.84 | M22: =(G22/1000)*K22 -> 87037.98 | N22: =L22/E4 -> 107.51615 | O22: =M22/F4 -> 102.2773
A23: 15 | B23: BLEACHING POWDER (S) | C23: 100 | F23: 0 | G23: ='06-07-26'!G23+'07-07-26'!F23 -> 0 | H23: =F23/E4 -> 0 | I23: =(C23-F23)+D23 -> 100 | J23: =G23/F4 -> 0 | K23: 41000 | L23: =(F23/1000)*K23 -> 0 | M23: =(G23/1000)*K23 -> 0 | N23: =L23/E4 -> 0 | O23: =M23/F4 -> 0
A24: 16 | B24: SODIUM HYPO CHLORIDE [HYPO] | C24: 355.6 | F24: 6 | G24: ='06-07-26'!G24+'07-07-26'!F24 -> 42 | H24: =F24/E4 -> 0.11538462 | I24: =(C24-F24)+D24 -> 349.6 | J24: =G24/F4 -> 0.049353702 | K24: 24000 | L24: =(F24/1000)*K24 -> 144 | M24: =(G24/1000)*K24 -> 1008 | N24: =L24/E4 -> 2.7692308 | O24: =M24/F4 -> 1.1844888
A25: 17 | B25: HCL [PULP MILL] | C25: 380 | F25: 0 | G25: ='06-07-26'!G25+'07-07-26'!F25 -> 0 | H25: =F25/E4 -> 0 | I25: =(C25-F25)+D25 -> 380 | J25: =G25/F4 -> 0 | K25: 13210 | L25: =(F25/1000)*K25 -> 0 | M25: =(G25/1000)*K25 -> 0 | N25: =L25/E4 -> 0 | O25: =M25/F4 -> 0
A26: 18 | B26: HCL [BOILER] | C26: 200 | F26: 5 | G26: ='06-07-26'!G26+'07-07-26'!F26 -> 50 | H26: =F26/E4 -> 0.096153846 | I26: =(C26-F26)+D26 -> 195 | J26: =G26/F4 -> 0.058754407 | K26: 14400 | L26: =(F26/1000)*K26 -> 72 | M26: =(G26/1000)*K26 -> 720 | N26: =L26/E4 -> 1.3846154 | O26: =M26/F4 -> 0.84606345
A27: 19 | B27: pH BOOSTER [3230] (L) | C27: 183.5 | F27: 3.5 | G27: ='06-07-26'!G27+'07-07-26'!F27 -> 25 | H27: =F27/E4 -> 0.067307692 | I27: =(C27-F27)+D27 -> 180 | J27: =G27/F4 -> 0.029377203 | K27: 102000 | L27: =(F27/1000)*K27 -> 357 | M27: =(G27/1000)*K27 -> 2550 | N27: =L27/E4 -> 6.8653846 | O27: =M27/F4 -> 2.9964747
A28: 20 | B28: ANTI SCALEN [3220] (L) | C28: 150 | F28: 5 | G28: ='06-07-26'!G28+'07-07-26'!F28 -> 35 | H28: =F28/E4 -> 0.096153846 | I28: =(C28-F28)+D28 -> 145 | J28: =G28/F4 -> 0.041128085 | K28: 107000 | L28: =(F28/1000)*K28 -> 535 | M28: =(G28/1000)*K28 -> 3745 | N28: =L28/E4 -> 10.288462 | O28: =M28/F4 -> 4.4007051
